Workbook
Name MY_FUNCTION1: LAMBDA(ARRAYFORMULA(NORMINV(_xludf.RANDARRAY('MoteCarlo_Sim OP'!$J$8,100),'MoteCarlo_Sim OP'!$J$2,'MoteCarlo_Sim OP'!$J$3)))
Name MY_FUNCTION1: LAMBDA(ARRAYFORMULA(NORMINV(_xludf.RANDARRAY('MoteCarlo_Sim (CP)'!$J$8,100),'MoteCarlo_Sim (CP)'!$J$2,'MoteCarlo_Sim (CP)'!$J$3)))
Name MY_FUNCTION1: LAMBDA(ARRAYFORMULA(NORMINV(_xludf.RANDARRAY('MoteCarlo_Sim OP'!$J$8,100),'MoteCarlo_Sim OP'!$J$2,'MoteCarlo_Sim OP'!$J$3)))

Sheet Work Sheet
A1: Date | B1: USD_RUB | C1: Rf_day | D1: INT_USD | E1: INT_RUB | F1: INT_R | G1: APPL_USD | H1: APPL_RUB | I1: APPL_R | J1: MCSF_USD | K1: MSCF_RUB | L1: MCSF_R | M1: CSC_USD | N1: CSC_RUB | O1: CSC_R | P1: DIS_USD | Q1: DIS_RUB | R1: DIS_R | S1: FDX_USD | T1: FDX_RUB | U1: FDX_R | V1: GMT_USD | W1: GMT_RUB | X1: GMT_R | Y1: CHV_USD | Z1: CHV_RUB | AA1: CHV_R | AB1: BNG_USD | AC1: BNG_RUB | AD1: BNG_R | AE1: AMZN_USD | AF1: AMZN_RUB | AG1: AMXN_R | AH1: S&P500_USD | AI1: S&P500_RUB | AJ1: S&P500_R
A2: 45200 | B2: =_xlfn.XLOOKUP(A2,'USD RUB'!B:B,'USD RUB'!C:C,"N/A") -> N/A | C2: =IFERROR(EXP(_xlfn.XLOOKUP(A2,'Bonds (CP)'!$A$4:$A$513,'Work Sheet'!$B$3:$B$512)/252)-1,"N/A") -> N/A | D2: =IFERROR(_xlfn.XLOOKUP($A2,Intel!$A$2:$A$502,Intel!$B$2:$B$502),"N/A") -> N/A | E2: =IF(OR(D2="N/A", $B2="N/A"),"N/A",D2*$B2) -> N/A | F2: N/A | G2: =IFERROR(_xlfn.XLOOKUP(A2,Apple!A:A,Apple!B:B),"N/A") -> N/A | H2: =IF(OR(G2="N/A", B2="N/A"),"N/A",G2*$B2) -> N/A | I2: ="N/A" -> N/A | J2: =IFERROR(_xlfn.XLOOKUP(A2,Microsoft!A:A,Microsoft!B:B),"N/A") -> N/A | K2: =IF(OR(J2="N/A",B2="N/A"),"N/A",J2*B2) -> N/A | L2: ="N/A" -> N/A | M2: =IFERROR(_xlfn.XLOOKUP($A2,Cisco!A:A,Cisco!B:B),"N/A") -> N/A | N2: =IF(OR(M2="N/A",$B2="N/A"),"N/A",M2*$B2) -> N/A | O2: N/A | P2: =IFERROR(_xlfn.XLOOKUP($A2,Disney!A:A,Disney!B:B),"N/A") -> N/A | Q2: =IF(OR(P2="N/A",$B2="N/A"),"N/A",P2*$B2) -> N/A | R2: N/A | S2: =_xlfn.XLOOKUP(A2,FedEx!A:A,FedEx!B:B,"N/A") -> N/A | T2: =IF(OR(S2="N/A",$B2="N/A"),"N/A",S2*$B2) -> N/A | U2: N/A | V2: =_xlfn.XLOOKUP($A2,'General Motors'!A:A,'General Motors'!B:B,"N/A") -> N/A | W2: =IF(OR(V2="N/A",$B2="N/A"),"N/A",V2*$B2) -> N/A | X2: N/A | Y2: =_xlfn.XLOOKUP($A2,Chevron!A:A,Chevron!B:B,"N/A") -> N/A | Z2: =IF(OR(Y2="N/A",$B2="N/A"),"N/A",Y2*$B2) -> N/A | AA2: N/A | AB2: =_xlfn.XLOOKUP($A2,Boeing!A:A,Boeing!B:B,"N/A") -> N/A | AC2: =IF(OR(AB2="N/A",$B2="N/A"),"N/A",AB2*$B2) -> N/A | AD2: N/A | AE2: =_xlfn.XLOOKUP(A2,Amazon!A:A,Amazon!B:B,"N/A") -> N/A | AF2: =IF(OR(AE2="N/A",$B2="N/A"),"N/A",AE2*$B2) -> N/A | AG2: N/A | AH2: N/A | AI2: N/A | AJ2: N/A
A3: 45201 | B3: =_xlfn.XLOOKUP(A3,'USD RUB'!B:B,'USD RUB'!C:C,"N/A") -> N/A | C3: =IFERROR(EXP(_xlfn.XLOOKUP(A3,'Bonds (CP)'!$A$4:$A$513,'Work Sheet'!$B$3:$B$512)/252)-1,"N/A") -> N/A | D3: =IFERROR(_xlfn.XLOOKUP($A3,Intel!$A$2:$A$502,Intel!$B$2:$B$502),"N/A") -> 35.46 | E3: =IF(OR(D3="N/A", $B3="N/A"),"N/A",D3*$B3) -> N/A | F3: =IF(E2="N/A", "N/A", IF(OR(E3="N/A",E2="N/A"),"N/A",E3/E2-1)) -> N/A | G3: =IFERROR(_xlfn.XLOOKUP(A3,Apple!A:A,Apple!B:B),"N/A") -> 173.75 | H3: =IF(OR(G3="N/A", B3="N/A"),"N/A",G3*$B3) -> N/A | I3: =IF(OR(H3="N/A",H2="N/A"), "N/A", H3/H2-1) -> N/A | J3: =IFERROR(_xlfn.XLOOKUP(A3,Microsoft!A:A,Microsoft!B:B),"N/A") -> 321.8 | K3: =IF(OR(J3="N/A",B3="N/A"),"N/A",J3*B3) -> N/A | L3: =IF(OR(K3="N/A",K2="N/A"), "N/A", K3/K2-1) -> N/A | M3: =IFERROR(_xlfn.XLOOKUP($A3,Cisco!A:A,Cisco!B:B),"N/A") -> 54.39 | N3: =IF(OR(M3="N/A",$B3="N/A"),"N/A",M3*$B3) -> N/A | O3: =IF(OR(N3="N/A",N2="N/A"),"N/A",N3/N2-1) -> N/A | P3: =IFERROR(_xlfn.XLOOKUP($A3,Disney!A:A,Disney!B:B),"N/A") -> 81.67 | Q3: =IF(OR(P3="N/A",$B3="N/A"),"N/A",P3*$B3) -> N/A | R3: =IF(OR(Q3="N/A",Q2="N/A"),"N/A",Q3/Q2-1) -> N/A | S3: =_xlfn.XLOOKUP(A3,FedEx!A:A,FedEx!B:B,"N/A") -> 265.11 | T3: =IF(OR(S3="N/A",$B3="N/A"),"N/A",S3*$B3) -> N/A | U3: =IF(OR(T3="N/A",T2="N/A"),"N/A",T3/T2-1) -> N/A | V3: =_xlfn.XLOOKUP($A3,'General Motors'!A:A,'General Motors'!B:B,"N/A") -> 32.47 | W3: =IF(OR(V3="N/A",$B3="N/A"),"N/A",V3*$B3) -> N/A | X3: =IF(OR(W3="N/A",W2="N/A"),"N/A",W3/W2-1) -> N/A | Y3: =_xlfn.XLOOKUP($A3,Chevron!A:A,Chevron!B:B,"N/A") -> 166.54 | Z3: =IF(OR(Y3="N/A",$B3="N/A"),"N/A",Y3*$B3) -> N/A | AA3: =IF(OR(Z3="N/A",Z2="N/A"),"N/A",Z3/Z2-1) -> N/A | AB3: =_xlfn.XLOOKUP($A3,Boeing!A:A,Boeing!B:B,"N/A") -> 187.83 | AC3: =IF(OR(AB3="N/A",$B3="N/A"),"N/A",AB3*$B3) -> N/A | AD3: =IF(OR(AC3="N/A",AC2="N/A"),"N/A",AC3/AC2-1) -> N/A | AE3: =_xlfn.XLOOKUP(A3,Amazon!A:A,Amazon!B:B,"N/A") -> 129.46 | AF3: =IF(OR(AE3="N/A",$B3="N/A"),"N/A",AE3*$B3) -> N/A | AG3: =IF(OR(AF3="N/A",AF2="N/A"),"N/A",AF3/AF2-1) -> N/A | AH3: 4288.39 | AI3: N/A | AJ3: N/A
A4: 45202 | B4: =_xlfn.XLOOKUP(A4,'USD RUB'!B:B,'USD RUB'!C:C,"N/A") -> 98.4785 | C4: =IFERROR(EXP(_xlfn.XLOOKUP(A4,'Bonds (CP)'!$A$4:$A$513,'Work Sheet'!$B$3:$B$512)/252)-1,"N/A") -> 0.47814467 | D4: =IFERROR(_xlfn.XLOOKUP($A4,Intel!$A$2:$A$502,Intel!$B$2:$B$502),"N/A") -> 35.69 | E4: =IF(OR(D4="N/A", $B4="N/A"),"N/A",D4*$B4) -> 3514.6977 | F4: =IF(E3="N/A", "N/A", IF(OR(E4="N/A",E3="N/A"),"N/A",E4/E3-1)) -> N/A | G4: =IFERROR(_xlfn.XLOOKUP(A4,Apple!A:A,Apple!B:B),"N/A") -> 172.4 | H4: =IF(OR(G4="N/A", B4="N/A"),"N/A",G4*$B4) -> 16977.693 | I4: =IF(OR(H4="N/A",H3="N/A"), "N/A", H4/H3-1) -> N/A | J4: =IFERROR(_xlfn.XLOOKUP(A4,Microsoft!A:A,Microsoft!B:B),"N/A") -> 313.39 | K4: =IF(OR(J4="N/A",B4="N/A"),"N/A",J4*B4) -> 30862.177 | L4: =IF(OR(K4="N/A",K3="N/A"), "N/A", K4/K3-1) -> N/A | M4: =IFERROR(_xlfn.XLOOKUP($A4,Cisco!A:A,Cisco!B:B),"N/A") -> 53.65 | N4: =IF(OR(M4="N/A",$B4="N/A"),"N/A",M4*$B4) -> 5283.3715 | O4: =IF(OR(N4="N/A",N3="N/A"),"N/A",N4/N3-1) -> N/A | P4: =IFERROR(_xlfn.XLOOKUP($A4,Disney!A:A,Disney!B:B),"N/A") -> 79.54 | Q4: =IF(OR(P4="N/A",$B4="N/A"),"N/A",P4*$B4) -> 7832.9799 | R4: =IF(OR(Q4="N/A",Q3="N/A"),"N/A",Q4/Q3-1) -> N/A | S4: =_xlfn.XLOOKUP(A4,FedEx!A:A,FedEx!B:B,"N/A") -> 260.19 | T4: =IF(OR(S4="N/A",$B4="N/A"),"N/A",S4*$B4) -> 25623.121 | U4: =IF(OR(T4="N/A",T3="N/A"),"N/A",T4/T3-1) -> N/A | V4: =_xlfn.XLOOKUP($A4,'General Motors'!A:A,'General Motors'!B:B,"N/A") -> 31.38 | W4: =IF(OR(V4="N/A",$B4="N/A"),"N/A",V4*$B4) -> 3090.2553 | X4: =IF(OR(W4="N/A",W3="N/A"),"N/A",W4/W3-1) -> N/A | Y4: =_xlfn.XLOOKUP($A4,Chevron!A:A,Chevron!B:B,"N/A") -> 166.93 | Z4: =IF(OR(Y4="N/A",$B4="N/A"),"N/A",Y4*$B4) -> 16439.016 | AA4: =IF(OR(Z4="N/A",Z3="N/A"),"N/A",Z4/Z3-1) -> N/A | AB4: =_xlfn.XLOOKUP($A4,Boeing!A:A,Boeing!B:B,"N/A") -> 188.92 | AC4: =IF(OR(AB4="N/A",$B4="N/A"),"N/A",AB4*$B4) -> 18604.558 | AD4: =IF(OR(AC4="N/A",AC3="N/A"),"N/A",AC4/AC3-1) -> N/A | AE4: =_xlfn.XLOOKUP(A4,Amazon!A:A,Amazon!B:B,"N/A") -> 124.72 | AF4: =IF(OR(AE4="N/A",$B4="N/A"),"N/A",AE4*$B4) -> 12282.239 | AG4: =IF(OR(AF4="N/A",AF3="N/A"),"N/A",AF4/AF3-1) -> N/A | AH4: 4229.45 | AI4: 416509.89 | AJ4: N/A
A5: 45203 | B5: =_xlfn.XLOOKUP(A5,'USD RUB'!B:B,'USD RUB'!C:C,"N/A") -> 99.2677 | C5: =IFERROR(EXP(_xlfn.XLOOKUP(A5,'Bonds (CP)'!$A$4:$A$513,'Work Sheet'!$B$3:$B$512)/252)-1,"N/A") -> 0.4827811 | D5: =IFERROR(_xlfn.XLOOKUP($A5,Intel!$A$2:$A$502,Intel!$B$2:$B$502),"N/A") -> 35.93 | E5: =IF(OR(D5="N/A", $B5="N/A"),"N/A",D5*$B5) -> 3566.6885 | F5: =IF(E4="N/A", "N/A", IF(OR(E5="N/A",E4="N/A"),"N/A",E5/E4-1)) -> 0.014792395 | G5: =IFERROR(_xlfn.XLOOKUP(A5,Apple!A:A,Apple!B:B),"N/A") -> 173.66 | H5: =IF(OR(G5="N/A", B5="N/A"),"N/A",G5*$B5) -> 17238.829 | I5: =IF(OR(H5="N/A",H4="N/A"), "N/A", H5/H4-1) -> 0.015381087 | J5: =IFERROR(_xlfn.XLOOKUP(A5,Microsoft!A:A,Microsoft!B:B),"N/A") -> 318.95 | K5: =IF(OR(J5="N/A",B5="N/A"),"N/A",J5*B5) -> 31661.433 | L5: =IF(OR(K5="N/A",K4="N/A"), "N/A", K5/K4-1) -> 0.025897583 | M5: =IFERROR(_xlfn.XLOOKUP($A5,Cisco!A:A,Cisco!B:B),"N/A") -> 53.45 | N5: =IF(OR(M5="N/A",$B5="N/A"),"N/A",M5*$B5) -> 5305.8586 | O5: =IF(OR(N5="N/A",N4="N/A"),"N/A",N5/N4-1) -> 0.0042561913 | P5: =IFERROR(_xlfn.XLOOKUP($A5,Disney!A:A,Disney!B:B),"N/A") -> 79.32 | Q5: =IF(OR(P5="N/A",$B5="N/A"),"N/A",P5*$B5) -> 7873.914 | R5: =IF(OR(Q5="N/A",Q4="N/A"),"N/A",Q5/Q4-1) -> 0.0052258623 | S5: =_xlfn.XLOOKUP(A5,FedEx!A:A,FedEx!B:B,"N/A") -> 260.05 | T5: =IF(OR(S5="N/A",$B5="N/A"),"N/A",S5*$B5) -> 25814.565 | U5: =IF(OR(T5="N/A",T4="N/A"),"N/A",T5/T4-1) -> 0.0074715516 | V5: =_xlfn.XLOOKUP($A5,'General Motors'!A:A,'General Motors'!B:B,"N/A") -> 31.04 | W5: =IF(OR(V5="N/A",$B5="N/A"),"N/A",V5*$B5) -> 3081.2694 | X5: =IF(OR(W5="N/A",W4="N/A"),"N/A",W5/W4-1) -> -0.0029078251 | Y5: =_xlfn.XLOOKUP($A5,Chevron!A:A,Chevron!B:B,"N/A") -> 163.04 | Z5: =IF(OR(Y5="N/A",$B5="N/A"),"N/A",Y5*$B5) -> 16184.606 | AA5: =IF(OR(Z5="N/A",Z4="N/A"),"N/A",Z5/Z4-1) -> -0.015475999 | AB5: =_xlfn.XLOOKUP($A5,Boeing!A:A,Boeing!B:B,"N/A") -> 186.73 | AC5: =IF(OR(AB5="N/A",$B5="N/A"),"N/A",AB5*$B5) -> 18536.258 | AD5: =IF(OR(AC5="N/A",AC4="N/A"),"N/A",AC5/AC4-1) -> -0.0036711755 | AE5: =_xlfn.XLOOKUP(A5,Amazon!A:A,Amazon!B:B,"N/A") -> 127 | AF5: =IF(OR(AE5="N/A",$B5="N/A"),"N/A",AE5*$B5) -> 12606.998 | AG5: =IF(OR(AF5="N/A",AF4="N/A"),"N/A",AF5/AF4-1) -> 0.026441384 | AH5: 4263.75 | AI5: 423252.66 | AJ5: 0.01618872
A6: 45204 | B6: =_xlfn.XLOOKUP(A6,'USD RUB'!B:B,'USD RUB'!C:C,"N/A") -> 99.4555 | C6: =IFERROR(EXP(_xlfn.XLOOKUP(A6,'Bonds (CP)'!$A$4:$A$513,'Work Sheet'!$B$3:$B$512)/252)-1,"N/A") -> 0.48388653 | D6: =IFERROR(_xlfn.XLOOKUP($A6,Intel!$A$2:$A$502,Intel!$B$2:$B$502),"N/A") -> 35.89 | E6: =IF(OR(D6="N/A", $B6="N/A"),"N/A",D6*$B6) -> 3569.4579 | F6: =IF(E5="N/A", "N/A", IF(OR(E6="N/A",E5="N/A"),"N/A",E6/E5-1)) -> 0.00077647208 | G6: =IFERROR(_xlfn.XLOOKUP(A6,Apple!A:A,Apple!B:B),"N/A") -> 174.91 | H6: =IF(OR(G6="N/A", B6="N/A"),"N/A",G6*$B6) -> 17395.762 | I6: =IF(OR(H6="N/A",H5="N/A"), "N/A", H6/H5-1) -> 0.0091034446 | J6: =IFERROR(_xlfn.XLOOKUP(A6,Microsoft!A:A,Microsoft!B:B),"N/A") -> 319.36 | K6: =IF(OR(J6="N/A",B6="N/A"),"N/A",J6*B6) -> 31762.108 | L6: =IF(OR(K6="N/A",K5="N/A"), "N/A", K6/K5-1) -> 0.0031797539 | M6: =IFERROR(_xlfn.XLOOKUP($A6,Cisco!A:A,Cisco!B:B),"N/A") -> 53.07 | N6: =IF(OR(M6="N/A",$B6="N/A"),"N/A",M6*$B6) -> 5278.1034 | O6: =IF(OR(N6="N/A",N5="N/A"),"N/A",N6/N5-1) -> -0.0052310441 | P6: =IFERROR(_xlfn.XLOOKUP($A6,Disney!A:A,Disney!B:B),"N/A") -> 80.81 | Q6: =IF(OR(P6="N/A",$B6="N/A"),"N/A",P6*$B6) -> 8036.999 | R6: =IF(OR(Q6="N/A",Q5="N/A"),"N/A",Q6/Q5-1) -> 0.020712062 | S6: =_xlfn.XLOOKUP(A6,FedEx!A:A,FedEx!B:B,"N/A") -> 259.16 | T6: =IF(OR(S6="N/A",$B6="N/A"),"N/A",S6*$B6) -> 25774.887 | U6: =IF(OR(T6="N/A",T5="N/A"),"N/A",T6/T5-1) -> -0.0015370394 | V6: =_xlfn.XLOOKUP($A6,'General Motors'!A:A,'General Motors'!B:B,"N/A") -> 30.31 | W6: =IF(OR(V6="N/A",$B6="N/A"),"N/A",V6*$B6) -> 3014.4962 | X6: =IF(OR(W6="N/A",W5="N/A"),"N/A",W6/W5-1) -> -0.02167068 | Y6: =_xlfn.XLOOKUP($A6,Chevron!A:A,Chevron!B:B,"N/A") -> 163.9 | Z6: =IF(OR(Y6="N/A",$B6="N/A"),"N/A",Y6*$B6) -> 16300.756 | AA6: =IF(OR(Z6="N/A",Z5="N/A"),"N/A",Z6/Z5-1) -> 0.0071766124 | AB6: =_xlfn.XLOOKUP($A6,Boeing!A:A,Boeing!B:B,"N/A") -> 186.29 | AC6: =IF(OR(AB6="N/A",$B6="N/A"),"N/A",AB6*$B6) -> 18527.565 | AD6: =IF(OR(AC6="N/A",AC5="N/A"),"N/A",AC6/AC5-1) -> -0.00046894719 | AE6: =_xlfn.XLOOKUP(A6,Amazon!A:A,Amazon!B:B,"N/A") -> 125.96 | AF6: =IF(OR(AE6="N/A",$B6="N/A"),"N/A",AE6*$B6) -> 12527.415 | AG6: =IF(OR(AF6="N/A",AF5="N/A"),"N/A",AF6/AF5-1) -> -0.0063126147 | AH6: 4258.19 | AI6: 423500.42 | AJ6: 0.00058537
A7: 45205 | B7: =_xlfn.XLOOKUP(A7,'USD RUB'!B:B,'USD RUB'!C:C,"N/A") -> 99.6762 | C7: =IFERROR(EXP(_xlfn.XLOOKUP(A7,'Bonds (CP)'!$A$4:$A$513,'Work Sheet'!$B$3:$B$512)/252)-1,"N/A") -> 0.48518668 | D7: =IFERROR(_xlfn.XLOOKUP($A7,Intel!$A$2:$A$502,Intel!$B$2:$B$502),"N/A") -> 36.19 | E7: =IF(OR(D7="N/A", $B7="N/A"),"N/A",D7*$B7) -> 3607.2817 | F7: =IF(E6="N/A", "N/A", IF(OR(E7="N/A",E6="N/A"),"N/A",E7/E6-1)) -> 0.010596506 | G7: =IFERROR(_xlfn.XLOOKUP(A7,Apple!A:A,Apple!B:B),"N/A") -> 177.49 | H7: =IF(OR(G7="N/A", B7="N/A"),"N/A",G7*$B7) -> 17691.529 | I7: =IF(OR(H7="N/A",H6="N/A"), "N/A", H7/H6-1) -> 0.017002258 | J7: =IFERROR(_xlfn.XLOOKUP(A7,Microsoft!A:A,Microsoft!B:B),"N/A") -> 327.26 | K7: =IF(OR(J7="N/A",B7="N/A"),"N/A",J7*B7) -> 32620.033 | L7: =IF(OR(K7="N/A",K6="N/A"), "N/A", K7/K6-1) -> 0.02701095 | M7: =IFERROR(_xlfn.XLOOKUP($A7,Cisco!A:A,Cisco!B:B),"N/A") -> 53.45 | N7: =IF(OR(M7="N/A",$B7="N/A"),"N/A",M7*$B7) -> 5327.6929 | O7: =IF(OR(N7="N/A",N6="N/A"),"N/A",N7/N6-1) -> 0.0093953266 | P7: =IFERROR(_xlfn.XLOOKUP($A7,Disney!A:A,Disney!B:B),"N/A") -> 82.94 | Q7: =IF(OR(P7="N/A",$B7="N/A"),"N/A",P7*$B7) -> 8267.144 | R7: =IF(OR(Q7="N/A",Q6="N/A"),"N/A",Q7/Q6-1) -> 0.028635698 | S7: =_xlfn.XLOOKUP(A7,FedEx!A:A,FedEx!B:B,"N/A") -> 257.9 | T7: =IF(OR(S7="N/A",$B7="N/A"),"N/A",S7*$B7) -> 25706.492 | U7: =IF(OR(T7="N/A",T6="N/A"),"N/A",T7/T6-1) -> -0.0026535674 | V7: =_xlfn.XLOOKUP($A7,'General Motors'!A:A,'General Motors'!B:B,"N/A") -> 30.9 | W7: =IF(OR(V7="N/A",$B7="N/A"),"N/A",V7*$B7) -> 3079.9946 | X7: =IF(OR(W7="N/A",W6="N/A"),"N/A",W7/W6-1) -> 0.021727801 | Y7: =_xlfn.XLOOKUP($A7,Chevron!A:A,Chevron!B:B,"N/A") -> 162.23 | Z7: =IF(OR(Y7="N/A",$B7="N/A"),"N/A",Y7*$B7) -> 16170.47 | AA7: =IF(OR(Z7="N/A",Z6="N/A"),"N/A",Z7/Z6-1) -> -0.0079926674 | AB7: =_xlfn.XLOOKUP($A7,Boeing!A:A,Boeing!B:B,"N/A") -> 187.38 | AC7: =IF(OR(AB7="N/A",$B7="N/A"),"N/A",AB7*$B7) -> 18677.326 | AD7: =IF(OR(AC7="N/A",AC6="N/A"),"N/A",AC7/AC6-1) -> 0.0080831593 | AE7: =_xlfn.XLOOKUP(A7,Amazon!A:A,Amazon!B:B,"N/A") -> 127.96 | AF7: =IF(OR(AE7="N/A",$B7="N/A"),"N/A",AE7*$B7) -> 12754.567 | AG7: =IF(OR(AF7="N/A",AF6="N/A"),"N/A",AF7/AF6-1) -> 0.018132374 | AH7: 879626 | AI7: 429454.91 | AJ7: 0.01406018
A8: 45206 | B8: =_xlfn.XLOOKUP(A8,'USD RUB'!B:B,'USD RUB'!C:C,"N/A") -> 100.4911 | C8: =IFERROR(EXP(_xlfn.XLOOKUP(A8,'Bonds (CP)'!$A$4:$A$513,'Work Sheet'!$B$3:$B$512)/252)-1,"N/A") -> N/A | D8: =IFERROR(_xlfn.XLOOKUP($A8,Intel!$A$2:$A$502,Intel!$B$2:$B$502),"N/A") -> N/A | E8: =IF(OR(D8="N/A", $B8="N/A"),"N/A",D8*$B8) -> N/A | F8: =IF(E7="N/A", "N/A", IF(OR(E8="N/A",E7="N/A"),"N/A",E8/E7-1)) -> N/A | G8: =IFERROR(_xlfn.XLOOKUP(A8,Apple!A:A,Apple!B:B),"N/A") -> N/A | H8: =IF(OR(G8="N/A", B8="N/A"),"N/A",G8*$B8) -> N/A | I8: =IF(OR(H8="N/A",H7="N/A"), "N/A", H8/H7-1) -> N/A | J8: =IFERROR(_xlfn.XLOOKUP(A8,Microsoft!A:A,Microsoft!B:B),"N/A") -> N/A | K8: =IF(OR(J8="N/A",B8="N/A"),"N/A",J8*B8) -> N/A | L8: =IF(OR(K8="N/A",K7="N/A"), "N/A", K8/K7-1) -> N/A | M8: =IFERROR(_xlfn.XLOOKUP($A8,Cisco!A:A,Cisco!B:B),"N/A") -> N/A | N8: =IF(OR(M8="N/A",$B8="N/A"),"N/A",M8*$B8) -> N/A | O8: =IF(OR(N8="N/A",N7="N/A"),"N/A",N8/N7-1) -> N/A | P8: =IFERROR(_xlfn.XLOOKUP($A8,Disney!A:A,Disney!B:B),"N/A") -> N/A | Q8: =IF(OR(P8="N/A",$B8="N/A"),"N/A",P8*$B8) -> N/A | R8: =IF(OR(Q8="N/A",Q7="N/A"),"N/A",Q8/Q7-1) -> N/A | S8: =_xlfn.XLOOKUP(A8,FedEx!A:A,FedEx!B:B,"N/A") -> N/A | T8: =IF(OR(S8="N/A",$B8="N/A"),"N/A",S8*$B8) -> N/A | U8: =IF(OR(T8="N/A",T7="N/A"),"N/A",T8/T7-1) -> N/A | V8: =_xlfn.XLOOKUP($A8,'General Motors'!A:A,'General Motors'!B:B,"N/A") -> N/A | W8: =IF(OR(V8="N/A",$B8="N/A"),"N/A",V8*$B8) -> N/A | X8: =IF(OR(W8="N/A",W7="N/A"),"N/A",W8/W7-1) -> N/A | Y8: =_xlfn.XLOOKUP($A8,Chevron!A:A,Chevron!B:B,"N/A") -> N/A | Z8: =IF(OR(Y8="N/A",$B8="N/A"),"N/A",Y8*$B8) -> N/A | AA8: =IF(OR(Z8="N/A",Z7="N/A"),"N/A",Z8/Z7-1) -> N/A | AB8: =_xlfn.XLOOKUP($A8,Boeing!A:A,Boeing!B:B,"N/A") -> N/A | AC8: =IF(OR(AB8="N/A",$B8="N/A"),"N/A",AB8*$B8) -> N/A | AD8: =IF(OR(AC8="N/A",AC7="N/A"),"N/A",AC8/AC7-1) -> N/A | AE8: =_xlfn.XLOOKUP(A8,Amazon!A:A,Amazon!B:B,"N/A") -> N/A | AF8: =IF(OR(AE8="N/A",$B8="N/A"),"N/A",AE8*$B8) -> N/A | AG8: =IF(OR(AF8="N/A",AF7="N/A"),"N/A",AF8/AF7-1) -> N/A | AH8: N/A | AI8: N/A | AJ8: N/A
A9: 45207 | B9: =_xlfn.XLOOKUP(A9,'USD RUB'!B:B,'USD RUB'!C:C,"N/A") -> N/A | C9: =IFERROR(EXP(_xlfn.XLOOKUP(A9,'Bonds (CP)'!$A$4:$A$513,'Work Sheet'!$B$3:$B$512)/252)-1,"N/A") -> N/A | D9: =IFERROR(_xlfn.XLOOKUP($A9,Intel!$A$2:$A$502,Intel!$B$2:$B$502),"N/A") -> N/A | E9: =IF(OR(D9="N/A", $B9="N/A"),"N/A",D9*$B9) -> N/A | F9: =IF(E8="N/A", "N/A", IF(OR(E9="N/A",E8="N/A"),"N/A",E9/E8-1)) -> N/A | G9: =IFERROR(_xlfn.XLOOKUP(A9,Apple!A:A,Apple!B:B),"N/A") -> N/A | H9: =IF(OR(G9="N/A", B9="N/A"),"N/A",G9*$B9) -> N/A | I9: =IF(OR(H9="N/A",H8="N/A"), "N/A", H9/H8-1) -> N/A | J9: =IFERROR(_xlfn.XLOOKUP(A9,Microsoft!A:A,Microsoft!B:B),"N/A") -> N/A | K9: =IF(OR(J9="N/A",B9="N/A"),"N/A",J9*B9) -> N/A | L9: =IF(OR(K9="N/A",K8="N/A"), "N/A", K9/K8-1) -> N/A | M9: =IFERROR(_xlfn.XLOOKUP($A9,Cisco!A:A,Cisco!B:B),"N/A") -> N/A | N9: =IF(OR(M9="N/A",$B9="N/A"),"N/A",M9*$B9) -> N/A | O9: =IF(OR(N9="N/A",N8="N/A"),"N/A",N9/N8-1) -> N/A | P9: =IFERROR(_xlfn.XLOOKUP($A9,Disney!A:A,Disney!B:B),"N/A") -> N/A | Q9: =IF(OR(P9="N/A",$B9="N/A"),"N/A",P9*$B9) -> N/A | R9: =IF(OR(Q9="N/A",Q8="N/A"),"N/A",Q9/Q8-1) -> N/A | S9: =_xlfn.XLOOKUP(A9,FedEx!A:A,FedEx!B:B,"N/A") -> N/A | T9: =IF(OR(S9="N/A",$B9="N/A"),"N/A",S9*$B9) -> N/A | U9: =IF(OR(T9="N/A",T8="N/A"),"N/A",T9/T8-1) -> N/A | V9: =_xlfn.XLOOKUP($A9,'General Motors'!A:A,'General Motors'!B:B,"N/A") -> N/A | W9: =IF(OR(V9="N/A",$B9="N/A"),"N/A",V9*$B9) -> N/A | X9: =IF(OR(W9="N/A",W8="N/A"),"N/A",W9/W8-1) -> N/A | Y9: =_xlfn.XLOOKUP($A9,Chevron!A:A,Chevron!B:B,"N/A") -> N/A | Z9: =IF(OR(Y9="N/A",$B9="N/A"),"N/A",Y9*$B9) -> N/A | AA9: =IF(OR(Z9="N/A",Z8="N/A"),"N/A",Z9/Z8-1) -> N/A | AB9: =_xlfn.XLOOKUP($A9,Boeing!A:A,Boeing!B:B,"N/A") -> N/A | AC9: =IF(OR(AB9="N/A",$B9="N/A"),"N/A",AB9*$B9) -> N/A | AD9: =IF(OR(AC9="N/A",AC8="N/A"),"N/A",AC9/AC8-1) -> N/A | AE9: =_xlfn.XLOOKUP(A9,Amazon!A:A,Amazon!B:B,"N/A") -> N/A | AF9: =IF(OR(AE9="N/A",$B9="N/A"),"N/A",AE9*$B9) -> N/A | AG9: =IF(OR(AF9="N/A",AF8="N/A"),"N/A",AF9/AF8-1) -> N/A | AH9: N/A | AI9: N/A | AJ9: N/A
A10: 45208 | B10: =_xlfn.XLOOKUP(A10,'USD RUB'!B:B,'USD RUB'!C:C,"N/A") -> N/A | C10: =IFERROR(EXP(_xlfn.XLOOKUP(A10,'Bonds (CP)'!$A$4:$A$513,'Work Sheet'!$B$3:$B$512)/252)-1,"N/A") -> 0.48999715 | D10: =IFERROR(_xlfn.XLOOKUP($A10,Intel!$A$2:$A$502,Intel!$B$2:$B$502),"N/A") -> 36.06 | E10: =IF(OR(D10="N/A", $B10="N/A"),"N/A",D10*$B10) -> N/A | F10: =IF(E9="N/A", "N/A", IF(OR(E10="N/A",E9="N/A"),"N/A",E10/E9-1)) -> N/A | G10: =IFERROR(_xlfn.XLOOKUP(A10,Apple!A:A,Apple!B:B),"N/A") -> 178.99 | H10: =IF(OR(G10="N/A", B10="N/A"),"N/A",G10*$B10) -> N/A | I10: =IF(OR(H10="N/A",H9="N/A"), "N/A", H10/H9-1) -> N/A | J10: =IFERROR(_xlfn.XLOOKUP(A10,Microsoft!A:A,Microsoft!B:B),"N/A") -> 329.82 | K10: =IF(OR(J10="N/A",B10="N/A"),"N/A",J10*B10) -> N/A | L10: =IF(OR(K10="N/A",K9="N/A"), "N/A", K10/K9-1) -> N/A | M10: =IFERROR(_xlfn.XLOOKUP($A10,Cisco!A:A,Cisco!B:B),"N/A") -> 53.92 | N10: =IF(OR(M10="N/A",$B10="N/A"),"N/A",M10*$B10) -> N/A | O10: =IF(OR(N10="N/A",N9="N/A"),"N/A",N10/N9-1) -> N/A | P10: =IFERROR(_xlfn.XLOOKUP($A10,Disney!A:A,Disney!B:B),"N/A") -> 84.7 | Q10: =IF(OR(P10="N/A",$B10="N/A"),"N/A",P10*$B10) -> N/A | R10: =IF(OR(Q10="N/A",Q9="N/A"),"N/A",Q10/Q9-1) -> N/A | S10: =_xlfn.XLOOKUP(A10,FedEx!A:A,FedEx!B:B,"N/A") -> 255.72 | T10: =IF(OR(S10="N/A",$B10="N/A"),"N/A",S10*$B10) -> N/A | U10: =IF(OR(T10="N/A",T9="N/A"),"N/A",T10/T9-1) -> N/A | V10: =_xlfn.XLOOKUP($A10,'General Motors'!A:A,'General Motors'!B:B,"N/A") -> 30.99 | W10: =IF(OR(V10="N/A",$B10="N/A"),"N/A",V10*$B10) -> N/A | X10: =IF(OR(W10="N/A",W9="N/A"),"N/A",W10/W9-1) -> N/A | Y10: =_xlfn.XLOOKUP($A10,Chevron!A:A,Chevron!B:B,"N/A") -> 166.72 | Z10: =IF(OR(Y10="N/A",$B10="N/A"),"N/A",Y10*$B10) -> N/A | AA10: =IF(OR(Z10="N/A",Z9="N/A"),"N/A",Z10/Z9-1) -> N/A | AB10: =_xlfn.XLOOKUP($A10,Boeing!A:A,Boeing!B:B,"N/A") -> 188.49 | AC10: =IF(OR(AB10="N/A",$B10="N/A"),"N/A",AB10*$B10) -> N/A | AD10: =IF(OR(AC10="N/A",AC9="N/A"),"N/A",AC10/AC9-1) -> N/A | AE10: =_xlfn.XLOOKUP(A10,Amazon!A:A,Amazon!B:B,"N/A") -> 128.26 | AF10: =IF(OR(AE10="N/A",$B10="N/A"),"N/A",AE10*$B10) -> N/A | AG10: =IF(OR(AF10="N/A",AF9="N/A"),"N/A",AF10/AF9-1) -> N/A | AH10: 4335.66 | AI10: N/A | AJ10: N/A
A11: 45209 | B11: =_xlfn.XLOOKUP(A11,'USD RUB'!B:B,'USD RUB'!C:C,"N/A") -> 101.3598 | C11: =IFERROR(EXP(_xlfn.XLOOKUP(A11,'Bonds (CP)'!$A$4:$A$513,'Work Sheet'!$B$3:$B$512)/252)-1,"N/A") -> N/A | D11: =IFERROR(_xlfn.XLOOKUP($A11,Intel!$A$2:$A$502,Intel!$B$2:$B$502),"N/A") -> 36.43 | E11: =IF(OR(D11="N/A", $B11="N/A"),"N/A",D11*$B11) -> 3692.5375 | F11: =IF(E10="N/A", "N/A", IF(OR(E11="N/A",E10="N/A"),"N/A",E11/E10-1)) -> N/A | G11: =IFERROR(_xlfn.XLOOKUP(A11,Apple!A:A,Apple!B:B),"N/A") -> 178.39 | H11: =IF(OR(G11="N/A", B11="N/A"),"N/A",G11*$B11) -> 18081.575 | I11: =IF(OR(H11="N/A",H10="N/A"), "N/A", H11/H10-1) -> N/A | J11: =IFERROR(_xlfn.XLOOKUP(A11,Microsoft!A:A,Microsoft!B:B),"N/A") -> 328.39 | K11: =IF(OR(J11="N/A",B11="N/A"),"N/A",J11*B11) -> 33285.545 | L11: =IF(OR(K11="N/A",K10="N/A"), "N/A", K11/K10-1) -> N/A | M11: =IFERROR(_xlfn.XLOOKUP($A11,Cisco!A:A,Cisco!B:B),"N/A") -> 53.87 | N11: =IF(OR(M11="N/A",$B11="N/A"),"N/A",M11*$B11) -> 5460.2524 | O11: =IF(OR(N11="N/A",N10="N/A"),"N/A",N11/N10-1) -> N/A | P11: =IFERROR(_xlfn.XLOOKUP($A11,Disney!A:A,Disney!B:B),"N/A") -> 84.99 | Q11: =IF(OR(P11="N/A",$B11="N/A"),"N/A",P11*$B11) -> 8614.5694 | R11: =IF(OR(Q11="N/A",Q10="N/A"),"N/A",Q11/Q10-1) -> N/A | S11: =_xlfn.XLOOKUP(A11,FedEx!A:A,FedEx!B:B,"N/A") -> 256.79 | T11: =IF(OR(S11="N/A",$B11="N/A"),"N/A",S11*$B11) -> 26028.183 | U11: =IF(OR(T11="N/A",T10="N/A"),"N/A",T11/T10-1) -> N/A | V11: =_xlfn.XLOOKUP($A11,'General Motors'!A:A,'General Motors'!B:B,"N/A") -> 31.48 | W11: =IF(OR(V11="N/A",$B11="N/A"),"N/A",V11*$B11) -> 3190.8065 | X11: =IF(OR(W11="N/A",W10="N/A"),"N/A",W11/W10-1) -> N/A | Y11: =_xlfn.XLOOKUP($A11,Chevron!A:A,Chevron!B:B,"N/A") -> 166.54 | Z11: =IF(OR(Y11="N/A",$B11="N/A"),"N/A",Y11*$B11) -> 16880.461 | AA11: =IF(OR(Z11="N/A",Z10="N/A"),"N/A",Z11/Z10-1) -> N/A | AB11: =_xlfn.XLOOKUP($A11,Boeing!A:A,Boeing!B:B,"N/A") -> 193.53 | AC11: =IF(OR(AB11="N/A",$B11="N/A"),"N/A",AB11*$B11) -> 19616.162 | AD11: =IF(OR(AC11="N/A",AC10="N/A"),"N/A",AC11/AC10-1) -> N/A | AE11: =_xlfn.XLOOKUP(A11,Amazon!A:A,Amazon!B:B,"N/A") -> 129.48 | AF11: =IF(OR(AE11="N/A",$B11="N/A"),"N/A",AE11*$B11) -> 13124.067 | AG11: =IF(OR(AF11="N/A",AF10="N/A"),"N/A",AF11/AF10-1) -> N/A | AH11: 4358.24 | AI11: 441750.33 | AJ11: N/A
A12: 45210 | B12: =_xlfn.XLOOKUP(A12,'USD RUB'!B:B,'USD RUB'!C:C,"N/A") -> 99.9349 | C12: =IFERROR(EXP(_xlfn.XLOOKUP(A12,'Bonds (CP)'!$A$4:$A$513,'Work Sheet'!$B$3:$B$512)/252)-1,"N/A") -> N/A | D12: =IFERROR(_xlfn.XLOOKUP($A12,Intel!$A$2:$A$502,Intel!$B$2:$B$502),"N/A") -> 36.88 | E12: =IF(OR(D12="N/A", $B12="N/A"),"N/A",D12*$B12) -> 3685.5991 | F12: =IF(E11="N/A", "N/A", IF(OR(E12="N/A",E11="N/A"),"N/A",E12/E11-1)) -> -0.0018790336 | G12: =IFERROR(_xlfn.XLOOKUP(A12,Apple!A:A,Apple!B:B),"N/A") -> 179.8 | H12: =IF(OR(G12="N/A", B12="N/A"),"N/A",G12*$B12) -> 17968.295 | I12: =IF(OR(H12="N/A",H11="N/A"), "N/A", H12/H11-1) -> -0.0062649246 | J12: =IFERROR(_xlfn.XLOOKUP(A12,Microsoft!A:A,Microsoft!B:B),"N/A") -> 332.42 | K12: =IF(OR(J12="N/A",B12="N/A"),"N/A",J12*B12) -> 33220.359 | L12: =IF(OR(K12="N/A",K11="N/A"), "N/A", K12/K11-1) -> -0.0019583655 | M12: =IFERROR(_xlfn.XLOOKUP($A12,Cisco!A:A,Cisco!B:B),"N/A") -> 53.66 | N12: =IF(OR(M12="N/A",$B12="N/A"),"N/A",M12*$B12) -> 5362.5067 | O12: =IF(OR(N12="N/A",N11="N/A"),"N/A",N12/N11-1) -> -0.017901314 | P12: =IFERROR(_xlfn.XLOOKUP($A12,Disney!A:A,Disney!B:B),"N/A") -> 84.85 | Q12: =IF(OR(P12="N/A",$B12="N/A"),"N/A",P12*$B12) -> 8479.4763 | R12: =IF(OR(Q12="N/A",Q11="N/A"),"N/A",Q12/Q11-1) -> -0.015681937 | S12: =_xlfn.XLOOKUP(A12,FedEx!A:A,FedEx!B:B,"N/A") -> 255.46 | T12: =IF(OR(S12="N/A",$B12="N/A"),"N/A",S12*$B12) -> 25529.37 | U12: =IF(OR(T12="N/A",T11="N/A"),"N/A",T12/T11-1) -> -0.019164361 | V12: =_xlfn.XLOOKUP($A12,'General Motors'!A:A,'General Motors'!B:B,"N/A") -> 30.98 | W12: =IF(OR(V12="N/A",$B12="N/A"),"N/A",V12*$B12) -> 3095.9832 | X12: =IF(OR(W12="N/A",W11="N/A"),"N/A",W12/W11-1) -> -0.02971766 | Y12: =_xlfn.XLOOKUP($A12,Chevron!A:A,Chevron!B:B,"N/A") -> 161.1 | Z12: =IF(OR(Y12="N/A",$B12="N/A"),"N/A",Y12*$B12) -> 16099.512 | AA12: =IF(OR(Z12="N/A",Z11="N/A"),"N/A",Z12/Z11-1) -> -0.04626347 | AB12: =_xlfn.XLOOKUP($A12,Boeing!A:A,Boeing!B:B,"N/A") -> 196.07 | AC12: =IF(OR(AB12="N/A",$B12="N/A"),"N/A",AB12*$B12) -> 19594.236 | AD12: =IF(OR(AC12="N/A",AC11="N/A"),"N/A",AC12/AC11-1) -> -0.0011177646 | AE12: =_xlfn.XLOOKUP(A12,Amazon!A:A,Amazon!B:B,"N/A") -> 131.83 | AF12: =IF(OR(AE12="N/A",$B12="N/A"),"N/A",AE12*$B12) -> 13174.418 | AG12: =IF(OR(AF12="N/A",AF11="N/A"),"N/A",AF12/AF11-1) -> 0.0038365366 | AH12: 4376.95 | AI12: 437410.06 | AJ12: -0.0098252
A13: 45211 | B13: =_xlfn.XLOOKUP(A13,'USD RUB'!B:B,'USD RUB'!C:C,"N/A") -> 99.9808 | C13: =IFERROR(EXP(_xlfn.XLOOKUP(A13,'Bonds (CP)'!$A$4:$A$513,'Work Sheet'!$B$3:$B$512)/252)-1,"N/A") -> 0.49514236 | D13: =IFERROR(_xlfn.XLOOKUP($A13,Intel!$A$2:$A$502,Intel!$B$2:$B$502),"N/A") -> 36.84 | E13: =IF(OR(D13="N/A", $B13="N/A"),"N/A",D13*$B13) -> 3683.2927 | F13: =IF(E12="N/A", "N/A", IF(OR(E13="N/A",E12="N/A"),"N/A",E13/E12-1)) -> -0.00062579785 | G13: =IFERROR(_xlfn.XLOOKUP(A13,Apple!A:A,Apple!B:B),"N/A") -> 180.71 | H13: =IF(OR(G13="N/A", B13="N/A"),"N/A",G13*$B13) -> 18067.53 | I13: =IF(OR(H13="N/A",H12="N/A"), "N/A", H13/H12-1) -> 0.0055228027 | J13: =IFERROR(_xlfn.XLOOKUP(A13,Microsoft!A:A,Microsoft!B:B),"N/A") -> 331.16 | K13: =IF(OR(J13="N/A",B13="N/A"),"N/A",J13*B13) -> 33109.642 | L13: =IF(OR(K13="N/A",K12="N/A"), "N/A", K13/K12-1) -> -0.0033328276 | M13: =IFERROR(_xlfn.XLOOKUP($A13,Cisco!A:A,Cisco!B:B),"N/A") -> 53.85 | N13: =IF(OR(M13="N/A",$B13="N/A"),"N/A",M13*$B13) -> 5383.9661 | O13: =IF(OR(N13="N/A",N12="N/A"),"N/A",N13/N12-1) -> 0.0040017378 | P13: =IFERROR(_xlfn.XLOOKUP($A13,Disney!A:A,Disney!B:B),"N/A") -> 84.35 | Q13: =IF(OR(P13="N/A",$B13="N/A"),"N/A",P13*$B13) -> 8433.3805 | R13: =IF(OR(Q13="N/A",Q12="N/A"),"N/A",Q13/Q12-1) -> -0.0054361594 | S13: =_xlfn.XLOOKUP(A13,FedEx!A:A,FedEx!B:B,"N/A") -> 252.04 | T13: =IF(OR(S13="N/A",$B13="N/A"),"N/A",S13*$B13) -> 25199.161 | U13: =IF(OR(T13="N/A",T12="N/A"),"N/A",T13/T12-1) -> -0.012934464 | V13: =_xlfn.XLOOKUP($A13,'General Motors'!A:A,'General Motors'!B:B,"N/A") -> 30.32 | W13: =IF(OR(V13="N/A",$B13="N/A"),"N/A",V13*$B13) -> 3031.4179 | X13: =IF(OR(W13="N/A",W12="N/A"),"N/A",W13/W12-1) -> -0.020854553 | Y13: =_xlfn.XLOOKUP($A13,Chevron!A:A,Chevron!B:B,"N/A") -> 161.23 | Z13: =IF(OR(Y13="N/A",$B13="N/A"),"N/A",Y13*$B13) -> 16119.904 | AA13: =IF(OR(Z13="N/A",Z12="N/A"),"N/A",Z13/Z12-1) -> 0.0012666218 | AB13: =_xlfn.XLOOKUP($A13,Boeing!A:A,Boeing!B:B,"N/A") -> 191.3 | AC13: =IF(OR(AB13="N/A",$B13="N/A"),"N/A",AB13*$B13) -> 19126.327 | AD13: =IF(OR(AC13="N/A",AC12="N/A"),"N/A",AC13/AC12-1) -> -0.023879921 | AE13: =_xlfn.XLOOKUP(A13,Amazon!A:A,Amazon!B:B,"N/A") -> 132.33 | AF13: =IF(OR(AE13="N/A",$B13="N/A"),"N/A",AE13*$B13) -> 13230.459 | AG13: =IF(OR(AF13="N/A",AF12="N/A"),"N/A",AF13/AF12-1) -> 0.0042538044 | AH13: 4349.61 | AI13: 434877.49 | AJ13: -0.0057899
A14: 45212 | B14: =_xlfn.XLOOKUP(A14,'USD RUB'!B:B,'USD RUB'!C:C,"N/A") -> 96.9948 | C14: =IFERROR(EXP(_xlfn.XLOOKUP(A14,'Bonds (CP)'!$A$4:$A$513,'Work Sheet'!$B$3:$B$512)/252)-1,"N/A") -> 0.48671214 | D14: =IFERROR(_xlfn.XLOOKUP($A14,Intel!$A$2:$A$502,Intel!$B$2:$B$502),"N/A") -> 35.97 | E14: =IF(OR(D14="N/A", $B14="N/A"),"N/A",D14*$B14) -> 3488.903 | F14: =IF(E13="N/A", "N/A", IF(OR(E14="N/A",E13="N/A"),"N/A",E14/E13-1)) -> -0.052776071 | G14: =IFERROR(_xlfn.XLOOKUP(A14,Apple!A:A,Apple!B:B),"N/A") -> 178.85 | H14: =IF(OR(G14="N/A", B14="N/A"),"N/A",G14*$B14) -> 17347.52 | I14: =IF(OR(H14="N/A",H13="N/A"), "N/A", H14/H13-1) -> -0.039851068 | J14: =IFERROR(_xlfn.XLOOKUP(A14,Microsoft!A:A,Microsoft!B:B),"N/A") -> 327.73 | K14: =IF(OR(J14="N/A",B14="N/A"),"N/A",J14*B14) -> 31788.106 | L14: =IF(OR(K14="N/A",K13="N/A"), "N/A", K14/K13-1) -> -0.03991393 | M14: =IFERROR(_xlfn.XLOOKUP($A14,Cisco!A:A,Cisco!B:B),"N/A") -> 53.77 | N14: =IF(OR(M14="N/A",$B14="N/A"),"N/A",M14*$B14) -> 5215.4104 | O14: =IF(OR(N14="N/A",N13="N/A"),"N/A",N14/N13-1) -> -0.031306974 | P14: =IFERROR(_xlfn.XLOOKUP($A14,Disney!A:A,Disney!B:B),"N/A") -> 84.35 | Q14: =IF(OR(P14="N/A",$B14="N/A"),"N/A",P14*$B14) -> 8181.5114 | R14: =IF(OR(Q14="N/A",Q13="N/A"),"N/A",Q14/Q13-1) -> -0.029865734 | S14: =_xlfn.XLOOKUP(A14,FedEx!A:A,FedEx!B:B,"N/A") -> 242.84 | T14: =IF(OR(S14="N/A",$B14="N/A"),"N/A",S14*$B14) -> 23554.217 | U14: =IF(OR(T14="N/A",T13="N/A"),"N/A",T14/T13-1) -> -0.065277713 | V14: =_xlfn.XLOOKUP($A14,'General Motors'!A:A,'General Motors'!B:B,"N/A") -> 29.66 | W14: =IF(OR(V14="N/A",$B14="N/A"),"N/A",V14*$B14) -> 2876.8658 | X14: =IF(OR(W14="N/A",W13="N/A"),"N/A",W14/W13-1) -> -0.050983433 | Y14: =_xlfn.XLOOKUP($A14,Chevron!A:A,Chevron!B:B,"N/A") -> 164.06 | Z14: =IF(OR(Y14="N/A",$B14="N/A"),"N/A",Y14*$B14) -> 15912.967 | AA14: =IF(OR(Z14="N/A",Z13="N/A"),"N/A",Z14/Z13-1) -> -0.01283739 | AB14: =_xlfn.XLOOKUP($A14,Boeing!A:A,Boeing!B:B,"N/A") -> 184.91 | AC14: =IF(OR(AB14="N/A",$B14="N/A"),"N/A",AB14*$B14) -> 17935.308 | AD14: =IF(OR(AC14="N/A",AC13="N/A"),"N/A",AC14/AC13-1) -> -0.06227116 | AE14: =_xlfn.XLOOKUP(A14,Amazon!A:A,Amazon!B:B,"N/A") -> 129.79 | AF14: =IF(OR(AE14="N/A",$B14="N/A"),"N/A",AE14*$B14) -> 12588.955 | AG14: =IF(OR(AF14="N/A",AF13="N/A"),"N/A",AF14/AF13-1) -> -0.048486916 | AH14: 4327.78 | AI14: 419772.16 | AJ14: -0.0347347
A15: 45213 | B15: =_xlfn.XLOOKUP(A15,'USD RUB'!B:B,'USD RUB'!C:C,"N/A") -> 97.3075 | C15: =IFERROR(EXP(_xlfn.XLOOKUP(A15,'Bonds (CP)'!$A$4:$A$513,'Work Sheet'!$B$3:$B$512)/252)-1,"N/A") -> N/A | D15: =IFERROR(_xlfn.XLOOKUP($A15,Intel!$A$2:$A$502,Intel!$B$2:$B$502),"N/A") -> N/A | E15: =IF(OR(D15="N/A", $B15="N/A"),"N/A",D15*$B15) -> N/A | F15: =IF(E14="N/A", "N/A", IF(OR(E15="N/A",E14="N/A"),"N/A",E15/E14-1)) -> N/A | G15: =IFERROR(_xlfn.XLOOKUP(A15,Apple!A:A,Apple!B:B),"N/A") -> N/A | H15: =IF(OR(G15="N/A", B15="N/A"),"N/A",G15*$B15) -> N/A | I15: =IF(OR(H15="N/A",H14="N/A"), "N/A", H15/H14-1) -> N/A | J15: =IFERROR(_xlfn.XLOOKUP(A15,Microsoft!A:A,Microsoft!B:B),"N/A") -> N/A | K15: =IF(OR(J15="N/A",B15="N/A"),"N/A",J15*B15) -> N/A | L15: =IF(OR(K15="N/A",K14="N/A"), "N/A", K15/K14-1) -> N/A | M15: =IFERROR(_xlfn.XLOOKUP($A15,Cisco!A:A,Cisco!B:B),"N/A") -> N/A | N15: =IF(OR(M15="N/A",$B15="N/A"),"N/A",M15*$B15) -> N/A | O15: =IF(OR(N15="N/A",N14="N/A"),"N/A",N15/N14-1) -> N/A | P15: =IFERROR(_xlfn.XLOOKUP($A15,Disney!A:A,Disney!B:B),"N/A") -> N/A | Q15: =IF(OR(P15="N/A",$B15="N/A"),"N/A",P15*$B15) -> N/A | R15: =IF(OR(Q15="N/A",Q14="N/A"),"N/A",Q15/Q14-1) -> N/A | S15: =_xlfn.XLOOKUP(A15,FedEx!A:A,FedEx!B:B,"N/A") -> N/A | T15: =IF(OR(S15="N/A",$B15="N/A"),"N/A",S15*$B15) -> N/A | U15: =IF(OR(T15="N/A",T14="N/A"),"N/A",T15/T14-1) -> N/A | V15: =_xlfn.XLOOKUP($A15,'General Motors'!A:A,'General Motors'!B:B,"N/A") -> N/A | W15: =IF(OR(V15="N/A",$B15="N/A"),"N/A",V15*$B15) -> N/A | X15: =IF(OR(W15="N/A",W14="N/A"),"N/A",W15/W14-1) -> N/A | Y15: =_xlfn.XLOOKUP($A15,Chevron!A:A,Chevron!B:B,"N/A") -> N/A | Z15: =IF(OR(Y15="N/A",$B15="N/A"),"N/A",Y15*$B15) -> N/A | AA15: =IF(OR(Z15="N/A",Z14="N/A"),"N/A",Z15/Z14-1) -> N/A | AB15: =_xlfn.XLOOKUP($A15,Boeing!A:A,Boeing!B:B,"N/A") -> N/A | AC15: =IF(OR(AB15="N/A",$B15="N/A"),"N/A",AB15*$B15) -> N/A | AD15: =IF(OR(AC15="N/A",AC14="N/A"),"N/A",AC15/AC14-1) -> N/A | AE15: =_xlfn.XLOOKUP(A15,Amazon!A:A,Amazon!B:B,"N/A") -> N/A | AF15: =IF(OR(AE15="N/A",$B15="N/A"),"N/A",AE15*$B15) -> N/A | AG15: =IF(OR(AF15="N/A",AF14="N/A"),"N/A",AF15/AF14-1) -> N/A | AH15: N/A | AI15: N/A | AJ15: N/A
A16: 45214 | B16: =_xlfn.XLOOKUP(A16,'USD RUB'!B:B,'USD RUB'!C:C,"N/A") -> N/A | C16: =IFERROR(EXP(_xlfn.XLOOKUP(A16,'Bonds (CP)'!$A$4:$A$513,'Work Sheet'!$B$3:$B$512)/252)-1,"N/A") -> N/A | D16: =IFERROR(_xlfn.XLOOKUP($A16,Intel!$A$2:$A$502,Intel!$B$2:$B$502),"N/A") -> N/A | E16: =IF(OR(D16="N/A", $B16="N/A"),"N/A",D16*$B16) -> N/A | F16: =IF(E15="N/A", "N/A", IF(OR(E16="N/A",E15="N/A"),"N/A",E16/E15-1)) -> N/A | G16: =IFERROR(_xlfn.XLOOKUP(A16,Apple!A:A,Apple!B:B),"N/A") -> N/A | H16: =IF(OR(G16="N/A", B16="N/A"),"N/A",G16*$B16) -> N/A | I16: =IF(OR(H16="N/A",H15="N/A"), "N/A", H16/H15-1) -> N/A | J16: =IFERROR(_xlfn.XLOOKUP(A16,Microsoft!A:A,Microsoft!B:B),"N/A") -> N/A | K16: =IF(OR(J16="N/A",B16="N/A"),"N/A",J16*B16) -> N/A | L16: =IF(OR(K16="N/A",K15="N/A"), "N/A", K16/K15-1) -> N/A | M16: =IFERROR(_xlfn.XLOOKUP($A16,Cisco!A:A,Cisco!B:B),"N/A") -> N/A | N16: =IF(OR(M16="N/A",$B16="N/A"),"N/A",M16*$B16) -> N/A | O16: =IF(OR(N16="N/A",N15="N/A"),"N/A",N16/N15-1) -> N/A | P16: =IFERROR(_xlfn.XLOOKUP($A16,Disney!A:A,Disney!B:B),"N/A") -> N/A | Q16: =IF(OR(P16="N/A",$B16="N/A"),"N/A",P16*$B16) -> N/A | R16: =IF(OR(Q16="N/A",Q15="N/A"),"N/A",Q16/Q15-1) -> N/A | S16: =_xlfn.XLOOKUP(A16,FedEx!A:A,FedEx!B:B,"N/A") -> N/A | T16: =IF(OR(S16="N/A",$B16="N/A"),"N/A",S16*$B16) -> N/A | U16: =IF(OR(T16="N/A",T15="N/A"),"N/A",T16/T15-1) -> N/A | V16: =_xlfn.XLOOKUP($A16,'General Motors'!A:A,'General Motors'!B:B,"N/A") -> N/A | W16: =IF(OR(V16="N/A",$B16="N/A"),"N/A",V16*$B16) -> N/A | X16: =IF(OR(W16="N/A",W15="N/A"),"N/A",W16/W15-1) -> N/A | Y16: =_xlfn.XLOOKUP($A16,Chevron!A:A,Chevron!B:B,"N/A") -> N/A | Z16: =IF(OR(Y16="N/A",$B16="N/A"),"N/A",Y16*$B16) -> N/A | AA16: =IF(OR(Z16="N/A",Z15="N/A"),"N/A",Z16/Z15-1) -> N/A | AB16: =_xlfn.XLOOKUP($A16,Boeing!A:A,Boeing!B:B,"N/A") -> N/A | AC16: =IF(OR(AB16="N/A",$B16="N/A"),"N/A",AB16*$B16) -> N/A | AD16: =IF(OR(AC16="N/A",AC15="N/A"),"N/A",AC16/AC15-1) -> N/A | AE16: =_xlfn.XLOOKUP(A16,Amazon!A:A,Amazon!B:B,"N/A") -> N/A | AF16: =IF(OR(AE16="N/A",$B16="N/A"),"N/A",AE16*$B16) -> N/A | AG16: =IF(OR(AF16="N/A",AF15="N/A"),"N/A",AF16/AF15-1) -> N/A | AH16: N/A | AI16: N/A | AJ16: N/A
A17: 45215 | B17: =_xlfn.XLOOKUP(A17,'USD RUB'!B:B,'USD RUB'!C:C,"N/A") -> N/A | C17: =IFERROR(EXP(_xlfn.XLOOKUP(A17,'Bonds (CP)'!$A$4:$A$513,'Work Sheet'!$B$3:$B$512)/252)-1,"N/A") -> 0.48698296 | D17: =IFERROR(_xlfn.XLOOKUP($A17,Intel!$A$2:$A$502,Intel!$B$2:$B$502),"N/A") -> 36.56 | E17: =IF(OR(D17="N/A", $B17="N/A"),"N/A",D17*$B17) -> N/A | F17: =IF(E16="N/A", "N/A", IF(OR(E17="N/A",E16="N/A"),"N/A",E17/E16-1)) -> N/A | G17: =IFERROR(_xlfn.XLOOKUP(A17,Apple!A:A,Apple!B:B),"N/A") -> 178.72 | H17: =IF(OR(G17="N/A", B17="N/A"),"N/A",G17*$B17) -> N/A | I17: =IF(OR(H17="N/A",H16="N/A"), "N/A", H17/H16-1) -> N/A | J17: =IFERROR(_xlfn.XLOOKUP(A17,Microsoft!A:A,Microsoft!B:B),"N/A") -> 332.64 | K17: =IF(OR(J17="N/A",B17="N/A"),"N/A",J17*B17) -> N/A | L17: =IF(OR(K17="N/A",K16="N/A"), "N/A", K17/K16-1) -> N/A | M17: =IFERROR(_xlfn.XLOOKUP($A17,Cisco!A:A,Cisco!B:B),"N/A") -> 54.16 | N17: =IF(OR(M17="N/A",$B17="N/A"),"N/A",M17*$B17) -> N/A | O17: =IF(OR(N17="N/A",N16="N/A"),"N/A",N17/N16-1) -> N/A | P17: =IFERROR(_xlfn.XLOOKUP($A17,Disney!A:A,Disney!B:B),"N/A") -> 85.71 | Q17: =IF(OR(P17="N/A",$B17="N/A"),"N/A",P17*$B17) -> N/A | R17: =IF(OR(Q17="N/A",Q16="N/A"),"N/A",Q17/Q16-1) -> N/A | S17: =_xlfn.XLOOKUP(A17,FedEx!A:A,FedEx!B:B,"N/A") -> 247.56 | T17: =IF(OR(S17="N/A",$B17="N/A"),"N/A",S17*$B17) -> N/A | U17: =IF(OR(T17="N/A",T16="N/A"),"N/A",T17/T16-1) -> N/A | V17: =_xlfn.XLOOKUP($A17,'General Motors'!A:A,'General Motors'!B:B,"N/A") -> 30.06 | W17: =IF(OR(V17="N/A",$B17="N/A"),"N/A",V17*$B17) -> N/A | X17: =IF(OR(W17="N/A",W16="N/A"),"N/A",W17/W16-1) -> N/A | Y17: =_xlfn.XLOOKUP($A17,Chevron!A:A,Chevron!B:B,"N/A") -> 165.4 | Z17: =IF(OR(Y17="N/A",$B17="N/A"),"N/A",Y17*$B17) -> N/A | AA17: =IF(OR(Z17="N/A",Z16="N/A"),"N/A",Z17/Z16-1) -> N/A | AB17: =_xlfn.XLOOKUP($A17,Boeing!A:A,Boeing!B:B,"N/A") -> 184.93 | AC17: =IF(OR(AB17="N/A",$B17="N/A"),"N/A",AB17*$B17) -> N/A | AD17: =IF(OR(AC17="N/A",AC16="N/A"),"N/A",AC17/AC16-1) -> N/A | AE17: =_xlfn.XLOOKUP(A17,Amazon!A:A,Amazon!B:B,"N/A") -> 132.55 | AF17: =IF(OR(AE17="N/A",$B17="N/A"),"N/A",AE17*$B17) -> N/A | AG17: =IF(OR(AF17="N/A",AF16="N/A"),"N/A",AF17/AF16-1) -> N/A | AH17: 4373.63 | AI17: N/A | AJ17: N/A
A18: 45216 | B18: =_xlfn.XLOOKUP(A18,'USD RUB'!B:B,'USD RUB'!C:C,"N/A") -> 97.2865 | C18: =IFERROR(EXP(_xlfn.XLOOKUP(A18,'Bonds (CP)'!$A$4:$A$513,'Work Sheet'!$B$3:$B$512)/252)-1,"N/A") -> 0.46946737 | D18: =IFERROR(_xlfn.XLOOKUP($A18,Intel!$A$2:$A$502,Intel!$B$2:$B$502),"N/A") -> 36.06 | E18: =IF(OR(D18="N/A", $B18="N/A"),"N/A",D18*$B18) -> 3508.1512 | F18: =IF(E17="N/A", "N/A", IF(OR(E18="N/A",E17="N/A"),"N/A",E18/E17-1)) -> N/A | G18: =IFERROR(_xlfn.XLOOKUP(A18,Apple!A:A,Apple!B:B),"N/A") -> 177.15 | H18: =IF(OR(G18="N/A", B18="N/A"),"N/A",G18*$B18) -> 17234.303 | I18: =IF(OR(H18="N/A",H17="N/A"), "N/A", H18/H17-1) -> N/A | J18: =IFERROR(_xlfn.XLOOKUP(A18,Microsoft!A:A,Microsoft!B:B),"N/A") -> 332.06 | K18: =IF(OR(J18="N/A",B18="N/A"),"N/A",J18*B18) -> 32304.955 | L18: =IF(OR(K18="N/A",K17="N/A"), "N/A", K18/K17-1) -> N/A | M18: =IFERROR(_xlfn.XLOOKUP($A18,Cisco!A:A,Cisco!B:B),"N/A") -> 53.94 | N18: =IF(OR(M18="N/A",$B18="N/A"),"N/A",M18*$B18) -> 5247.6338 | O18: =IF(OR(N18="N/A",N17="N/A"),"N/A",N18/N17-1) -> N/A | P18: =IFERROR(_xlfn.XLOOKUP($A18,Disney!A:A,Disney!B:B),"N/A") -> 86.2 | Q18: =IF(OR(P18="N/A",$B18="N/A"),"N/A",P18*$B18) -> 8386.0963 | R18: =IF(OR(Q18="N/A",Q17="N/A"),"N/A",Q18/Q17-1) -> N/A | S18: =_xlfn.XLOOKUP(A18,FedEx!A:A,FedEx!B:B,"N/A") -> 248.03 | T18: =IF(OR(S18="N/A",$B18="N/A"),"N/A",S18*$B18) -> 24129.971 | U18: =IF(OR(T18="N/A",T17="N/A"),"N/A",T18/T17-1) -> N/A | V18: =_xlfn.XLOOKUP($A18,'General Motors'!A:A,'General Motors'!B:B,"N/A") -> 30.33 | W18: =IF(OR(V18="N/A",$B18="N/A"),"N/A",V18*$B18) -> 2950.6995 | X18: =IF(OR(W18="N/A",W17="N/A"),"N/A",W18/W17-1) -> N/A | Y18: =_xlfn.XLOOKUP($A18,Chevron!A:A,Chevron!B:B,"N/A") -> 167.59 | Z18: =IF(OR(Y18="N/A",$B18="N/A"),"N/A",Y18*$B18) -> 16304.245 | AA18: =IF(OR(Z18="N/A",Z17="N/A"),"N/A",Z18/Z17-1) -> N/A | AB18: =_xlfn.XLOOKUP($A18,Boeing!A:A,Boeing!B:B,"N/A") -> 185.6 | AC18: =IF(OR(AB18="N/A",$B18="N/A"),"N/A",AB18*$B18) -> 18056.374 | AD18: =IF(OR(AC18="N/A",AC17="N/A"),"N/A",AC18/AC17-1) -> N/A | AE18: =_xlfn.XLOOKUP(A18,Amazon!A:A,Amazon!B:B,"N/A") -> 131.47 | AF18: =IF(OR(AE18="N/A",$B18="N/A"),"N/A",AE18*$B18) -> 12790.256 | AG18: =IF(OR(AF18="N/A",AF17="N/A"),"N/A",AF18/AF17-1) -> N/A | AH18: 903278 | AI18: 425453.32 | AJ18: N/A
A19: 45217 | B19: =_xlfn.XLOOKUP(A19,'USD RUB'!B:B,'USD RUB'!C:C,"N/A") -> 97.3458 | C19: =IFERROR(EXP(_xlfn.XLOOKUP(A19,'Bonds (CP)'!$A$4:$A$513,'Work Sheet'!$B$3:$B$512)/252)-1,"N/A") -> 0.47129192 | D19: =IFERROR(_xlfn.XLOOKUP($A19,Intel!$A$2:$A$502,Intel!$B$2:$B$502),"N/A") -> 35.64 | E19: =IF(OR(D19="N/A", $B19="N/A"),"N/A",D19*$B19) -> 3469.4043 | F19: =IF(E18="N/A", "N/A", IF(OR(E19="N/A",E18="N/A"),"N/A",E19/E18-1)) -> -0.011044814 | G19: =IFERROR(_xlfn.XLOOKUP(A19,Apple!A:A,Apple!B:B),"N/A") -> 175.84 | H19: =IF(OR(G19="N/A", B19="N/A"),"N/A",G19*$B19) -> 17117.285 | I19: =IF(OR(H19="N/A",H18="N/A"), "N/A", H19/H18-1) -> -0.0067898307 | J19: =IFERROR(_xlfn.XLOOKUP(A19,Microsoft!A:A,Microsoft!B:B),"N/A") -> 330.11 | K19: =IF(OR(J19="N/A",B19="N/A"),"N/A",J19*B19) -> 32134.822 | L19: =IF(OR(K19="N/A",K18="N/A"), "N/A", K19/K18-1) -> -0.0052664723 | M19: =IFERROR(_xlfn.XLOOKUP($A19,Cisco!A:A,Cisco!B:B),"N/A") -> 53.77 | N19: =IF(OR(M19="N/A",$B19="N/A"),"N/A",M19*$B19) -> 5234.2837 | O19: =IF(OR(N19="N/A",N18="N/A"),"N/A",N19/N18-1) -> -0.0025440312 | P19: =IFERROR(_xlfn.XLOOKUP($A19,Disney!A:A,Disney!B:B),"N/A") -> 84.68 | Q19: =IF(OR(P19="N/A",$B19="N/A"),"N/A",P19*$B19) -> 8243.2423 | R19: =IF(OR(Q19="N/A",Q18="N/A"),"N/A",Q19/Q18-1) -> -0.017034619 | S19: =_xlfn.XLOOKUP(A19,FedEx!A:A,FedEx!B:B,"N/A") -> 243.61 | T19: =IF(OR(S19="N/A",$B19="N/A"),"N/A",S19*$B19) -> 23714.41 | U19: =IF(OR(T19="N/A",T18="N/A"),"N/A",T19/T18-1) -> -0.017221747 | V19: =_xlfn.XLOOKUP($A19,'General Motors'!A:A,'General Motors'!B:B,"N/A") -> 29.48 | W19: =IF(OR(V19="N/A",$B19="N/A"),"N/A",V19*$B19) -> 2869.7542 | X19: =IF(OR(W19="N/A",W18="N/A"),"N/A",W19/W18-1) -> -0.0274326 | Y19: =_xlfn.XLOOKUP($A19,Chevron!A:A,Chevron!B:B,"N/A") -> 168.92 | Z19: =IF(OR(Y19="N/A",$B19="N/A"),"N/A",Y19*$B19) -> 16443.653 | AA19: =IF(OR(Z19="N/A",Z18="N/A"),"N/A",Z19/Z18-1) -> 0.0085504116 | AB19: =_xlfn.XLOOKUP($A19,Boeing!A:A,Boeing!B:B,"N/A") -> 185.69 | AC19: =IF(OR(AB19="N/A",$B19="N/A"),"N/A",AB19*$B19) -> 18076.142 | AD19: =IF(OR(AC19="N/A",AC18="N/A"),"N/A",AC19/AC18-1) -> 0.0010947492 | AE19: =_xlfn.XLOOKUP(A19,Amazon!A:A,Amazon!B:B,"N/A") -> 128.13 | AF19: =IF(OR(AE19="N/A",$B19="N/A"),"N/A",AE19*$B19) -> 12472.917 | AG19: =IF(OR(AF19="N/A",AF18="N/A"),"N/A",AF19/AF18-1) -> -0.024810981 | AH19: 881848 | AI19: 420008.19 | AJ19: -0.0127984
A20: 45218 | B20: =_xlfn.XLOOKUP(A20,'USD RUB'!B:B,'USD RUB'!C:C,"N/A") -> 97.3724 | C20: =IFERROR(EXP(_xlfn.XLOOKUP(A20,'Bonds (CP)'!$A$4:$A$513,'Work Sheet'!$B$3:$B$512)/252)-1,"N/A") -> N/A | D20: =IFERROR(_xlfn.XLOOKUP($A20,Intel!$A$2:$A$502,Intel!$B$2:$B$502),"N/A") -> 35.67 | E20: =IF(OR(D20="N/A", $B20="N/A"),"N/A",D20*$B20) -> 3473.2735 | F20: =IF(E19="N/A", "N/A", IF(OR(E20="N/A",E19="N/A"),"N/A",E20/E19-1)) -> 0.0011152335 | G20: =IFERROR(_xlfn.XLOOKUP(A20,Apple!A:A,Apple!B:B),"N/A") -> 175.46 | H20: =IF(OR(G20="N/A", B20="N/A"),"N/A",G20*$B20) -> 17084.961 | I20: =IF(OR(H20="N/A",H19="N/A"), "N/A", H20/H19-1) -> -0.0018883933 | J20: =IFERROR(_xlfn.XLOOKUP(A20,Microsoft!A:A,Microsoft!B:B),"N/A") -> 331.32 | K20: =IF(OR(J20="N/A",B20="N/A"),"N/A",J20*B20) -> 32261.424 | L20: =IF(OR(K20="N/A",K19="N/A"), "N/A", K20/K19-1) -> 0.0039396991 | M20: =IFERROR(_xlfn.XLOOKUP($A20,Cisco!A:A,Cisco!B:B),"N/A") -> 53.32 | N20: =IF(OR(M20="N/A",$B20="N/A"),"N/A",M20*$B20) -> 5191.8964 | O20: =IF(OR(N20="N/A",N19="N/A"),"N/A",N20/N19-1) -> -0.0080980132 | P20: =IFERROR(_xlfn.XLOOKUP($A20,Disney!A:A,Disney!B:B),"N/A") -> 83.25 | Q20: =IF(OR(P20="N/A",$B20="N/A"),"N/A",P20*$B20) -> 8106.2523 | R20: =IF(OR(Q20="N/A",Q19="N/A"),"N/A",Q20/Q19-1) -> -0.016618466 | S20: =_xlfn.XLOOKUP(A20,FedEx!A:A,FedEx!B:B,"N/A") -> 243.29 | T20: =IF(OR(S20="N/A",$B20="N/A"),"N/A",S20*$B20) -> 23689.731 | U20: =IF(OR(T20="N/A",T19="N/A"),"N/A",T20/T19-1) -> -0.0010406812 | V20: =_xlfn.XLOOKUP($A20,'General Motors'!A:A,'General Motors'!B:B,"N/A") -> 29.33 | W20: =IF(OR(V20="N/A",$B20="N/A"),"N/A",V20*$B20) -> 2855.9325 | X20: =IF(OR(W20="N/A",W19="N/A"),"N/A",W20/W19-1) -> -0.0048163331 | Y20: =_xlfn.XLOOKUP($A20,Chevron!A:A,Chevron!B:B,"N/A") -> 169.1 | Z20: =IF(OR(Y20="N/A",$B20="N/A"),"N/A",Y20*$B20) -> 16465.673 | AA20: =IF(OR(Z20="N/A",Z19="N/A"),"N/A",Z20/Z19-1) -> 0.001339137 | AB20: =_xlfn.XLOOKUP($A20,Boeing!A:A,Boeing!B:B,"N/A") -> 182.79 | AC20: =IF(OR(AB20="N/A",$B20="N/A"),"N/A",AB20*$B20) -> 17798.701 | AD20: =IF(OR(AC20="N/A",AC19="N/A"),"N/A",AC20/AC19-1) -> -0.015348442 | AE20: =_xlfn.XLOOKUP(A20,Amazon!A:A,Amazon!B:B,"N/A") -> 128.4 | AF20: =IF(OR(AE20="N/A",$B20="N/A"),"N/A",AE20*$B20) -> 12502.616 | AG20: =IF(OR(AF20="N/A",AF19="N/A"),"N/A",AF20/AF19-1) -> 0.0023810633 | AH20: 4278 | AI20: 416559.13 | AJ20: -0.0082119
A21: 45219 | B21: =_xlfn.XLOOKUP(A21,'USD RUB'!B:B,'USD RUB'!C:C,"N/A") -> 97.3074 | C21: =IFERROR(EXP(_xlfn.XLOOKUP(A21,'Bonds (CP)'!$A$4:$A$513,'Work Sheet'!$B$3:$B$512)/252)-1,"N/A") -> N/A | D21: =IFERROR(_xlfn.XLOOKUP($A21,Intel!$A$2:$A$502,Intel!$B$2:$B$502),"N/A") -> 34.92 | E21: =IF(OR(D21="N/A", $B21="N/A"),"N/A",D21*$B21) -> 3397.9744 | F21: =IF(E20="N/A", "N/A", IF(OR(E21="N/A",E20="N/A"),"N/A",E21/E20-1)) -> -0.021679577 | G21: =IFERROR(_xlfn.XLOOKUP(A21,Apple!A:A,Apple!B:B),"N/A") -> 172.88 | H21: =IF(OR(G21="N/A", B21="N/A"),"N/A",G21*$B21) -> 16822.503 | I21: =IF(OR(H21="N/A",H20="N/A"), "N/A", H21/H20-1) -> -0.015361931 | J21: =IFERROR(_xlfn.XLOOKUP(A21,Microsoft!A:A,Microsoft!B:B),"N/A") -> 326.67 | K21: =IF(OR(J21="N/A",B21="N/A"),"N/A",J21*B21) -> 31787.408 | L21: =IF(OR(K21="N/A",K20="N/A"), "N/A", K21/K20-1) -> -0.014692942 | M21: =IFERROR(_xlfn.XLOOKUP($A21,Cisco!A:A,Cisco!B:B),"N/A") -> 52.93 | N21: =IF(OR(M21="N/A",$B21="N/A"),"N/A",M21*$B21) -> 5150.4807 | O21: =IF(OR(N21="N/A",N20="N/A"),"N/A",N21/N20-1) -> -0.0079769863 | P21: =IFERROR(_xlfn.XLOOKUP($A21,Disney!A:A,Disney!B:B),"N/A") -> 82.65 | Q21: =IF(OR(P21="N/A",$B21="N/A"),"N/A",P21*$B21) -> 8042.4566 | R21: =IF(OR(Q21="N/A",Q20="N/A"),"N/A",Q21/Q20-1) -> -0.0078699364 | S21: =_xlfn.XLOOKUP(A21,FedEx!A:A,FedEx!B:B,"N/A") -> 240.62 | T21: =IF(OR(S21="N/A",$B21="N/A"),"N/A",S21*$B21) -> 23414.107 | U21: =IF(OR(T21="N/A",T20="N/A"),"N/A",T21/T20-1) -> -0.011634771 | V21: =_xlfn.XLOOKUP($A21,'General Motors'!A:A,'General Motors'!B:B,"N/A") -> 29.66 | W21: =IF(OR(V21="N/A",$B21="N/A"),"N/A",V21*$B21) -> 2886.1375 | X21: =IF(OR(W21="N/A",W20="N/A"),"N/A",W21/W20-1) -> 0.010576228 | Y21: =_xlfn.XLOOKUP($A21,Chevron!A:A,Chevron!B:B,"N/A") -> 166.83 | Z21: =IF(OR(Y21="N/A",$B21="N/A"),"N/A",Y21*$B21) -> 16233.794 | AA21: =IF(OR(Z21="N/A",Z20="N/A"),"N/A",Z21/Z20-1) -> -0.014082589 | AB21: =_xlfn.XLOOKUP($A21,Boeing!A:A,Boeing!B:B,"N/A") -> 180.04 | AC21: =IF(OR(AB21="N/A",$B21="N/A"),"N/A",AB21*$B21) -> 17519.224 | AD21: =IF(OR(AC21="N/A",AC20="N/A"),"N/A",AC21/AC20-1) -> -0.015702084 | AE21: =_xlfn.XLOOKUP(A21,Amazon!A:A,Amazon!B:B,"N/A") -> 125.17 | AF21: =IF(OR(AE21="N/A",$B21="N/A"),"N/A",AE21*$B21) -> 12179.967 | AG21: =IF(OR(AF21="N/A",AF20="N/A"),"N/A",AF21/AF20-1) -> -0.025806511 | AH21: 4224.16 | AI21: 411042.03 | AJ21: -0.0132445
A22: 45220 | B22: =_xlfn.XLOOKUP(A22,'USD RUB'!B:B,'USD RUB'!C:C,"N/A") -> 95.9053 | C22: =IFERROR(EXP(_xlfn.XLOOKUP(A22,'Bonds (CP)'!$A$4:$A$513,'Work Sheet'!$B$3:$B$512)/252)-1,"N/A") -> N/A | D22: =IFERROR(_xlfn.XLOOKUP($A22,Intel!$A$2:$A$502,Intel!$B$2:$B$502),"N/A") -> N/A | E22: =IF(OR(D22="N/A", $B22="N/A"),"N/A",D22*$B22) -> N/A | F22: =IF(E21="N/A", "N/A", IF(OR(E22="N/A",E21="N/A"),"N/A",E22/E21-1)) -> N/A | G22: =IFERROR(_xlfn.XLOOKUP(A22,Apple!A:A,Apple!B:B),"N/A") -> N/A | H22: =IF(OR(G22="N/A", B22="N/A"),"N/A",G22*$B22) -> N/A | I22: =IF(OR(H22="N/A",H21="N/A"), "N/A", H22/H21-1) -> N/A | J22: =IFERROR(_xlfn.XLOOKUP(A22,Microsoft!A:A,Microsoft!B:B),"N/A") -> N/A | K22: =IF(OR(J22="N/A",B22="N/A"),"N/A",J22*B22) -> N/A | L22: =IF(OR(K22="N/A",K21="N/A"), "N/A", K22/K21-1) -> N/A | M22: =IFERROR(_xlfn.XLOOKUP($A22,Cisco!A:A,Cisco!B:B),"N/A") -> N/A | N22: =IF(OR(M22="N/A",$B22="N/A"),"N/A",M22*$B22) -> N/A | O22: =IF(OR(N22="N/A",N21="N/A"),"N/A",N22/N21-1) -> N/A | P22: =IFERROR(_xlfn.XLOOKUP($A22,Disney!A:A,Disney!B:B),"N/A") -> N/A | Q22: =IF(OR(P22="N/A",$B22="N/A"),"N/A",P22*$B22) -> N/A | R22: =IF(OR(Q22="N/A",Q21="N/A"),"N/A",Q22/Q21-1) -> N/A | S22: =_xlfn.XLOOKUP(A22,FedEx!A:A,FedEx!B:B,"N/A") -> N/A | T22: =IF(OR(S22="N/A",$B22="N/A"),"N/A",S22*$B22) -> N/A | U22: =IF(OR(T22="N/A",T21="N/A"),"N/A",T22/T21-1) -> N/A | V22: =_xlfn.XLOOKUP($A22,'General Motors'!A:A,'General Motors'!B:B,"N/A") -> N/A | W22: =IF(OR(V22="N/A",$B22="N/A"),"N/A",V22*$B22) -> N/A | X22: =IF(OR(W22="N/A",W21="N/A"),"N/A",W22/W21-1) -> N/A | Y22: =_xlfn.XLOOKUP($A22,Chevron!A:A,Chevron!B:B,"N/A") -> N/A | Z22: =IF(OR(Y22="N/A",$B22="N/A"),"N/A",Y22*$B22) -> N/A | AA22: =IF(OR(Z22="N/A",Z21="N/A"),"N/A",Z22/Z21-1) -> N/A | AB22: =_xlfn.XLOOKUP($A22,Boeing!A:A,Boeing!B:B,"N/A") -> N/A | AC22: =IF(OR(AB22="N/A",$B22="N/A"),"N/A",AB22*$B22) -> N/A | AD22: =IF(OR(AC22="N/A",AC21="N/A"),"N/A",AC22/AC21-1) -> N/A | AE22: =_xlfn.XLOOKUP(A22,Amazon!A:A,Amazon!B:B,"N/A") -> N/A | AF22: =IF(OR(AE22="N/A",$B22="N/A"),"N/A",AE22*$B22) -> N/A | AG22: =IF(OR(AF22="N/A",AF21="N/A"),"N/A",AF22/AF21-1) -> N/A | AH22: N/A | AI22: N/A | AJ22: N/A
A23: 45221 | B23: =_xlfn.XLOOKUP(A23,'USD RUB'!B:B,'USD RUB'!C:C,"N/A") -> N/A | C23: =IFERROR(EXP(_xlfn.XLOOKUP(A23,'Bonds (CP)'!$A$4:$A$513,'Work Sheet'!$B$3:$B$512)/252)-1,"N/A") -> N/A | D23: =IFERROR(_xlfn.XLOOKUP($A23,Intel!$A$2:$A$502,Intel!$B$2:$B$502),"N/A") -> N/A | E23: =IF(OR(D23="N/A", $B23="N/A"),"N/A",D23*$B23) -> N/A | F23: =IF(E22="N/A", "N/A", IF(OR(E23="N/A",E22="N/A"),"N/A",E23/E22-1)) -> N/A | G23: =IFERROR(_xlfn.XLOOKUP(A23,Apple!A:A,Apple!B:B),"N/A") -> N/A | H23: =IF(OR(G23="N/A", B23="N/A"),"N/A",G23*$B23) -> N/A | I23: =IF(OR(H23="N/A",H22="N/A"), "N/A", H23/H22-1) -> N/A | J23: =IFERROR(_xlfn.XLOOKUP(A23,Microsoft!A:A,Microsoft!B:B),"N/A") -> N/A | K23: =IF(OR(J23="N/A",B23="N/A"),"N/A",J23*B23) -> N/A | L23: =IF(OR(K23="N/A",K22="N/A"), "N/A", K23/K22-1) -> N/A | M23: =IFERROR(_xlfn.XLOOKUP($A23,Cisco!A:A,Cisco!B:B),"N/A") -> N/A | N23: =IF(OR(M23="N/A",$B23="N/A"),"N/A",M23*$B23) -> N/A | O23: =IF(OR(N23="N/A",N22="N/A"),"N/A",N23/N22-1) -> N/A | P23: =IFERROR(_xlfn.XLOOKUP($A23,Disney!A:A,Disney!B:B),"N/A") -> N/A | Q23: =IF(OR(P23="N/A",$B23="N/A"),"N/A",P23*$B23) -> N/A | R23: =IF(OR(Q23="N/A",Q22="N/A"),"N/A",Q23/Q22-1) -> N/A | S23: =_xlfn.XLOOKUP(A23,FedEx!A:A,FedEx!B:B,"N/A") -> N/A | T23: =IF(OR(S23="N/A",$B23="N/A"),"N/A",S23*$B23) -> N/A | U23: =IF(OR(T23="N/A",T22="N/A"),"N/A",T23/T22-1) -> N/A | V23: =_xlfn.XLOOKUP($A23,'General Motors'!A:A,'General Motors'!B:B,"N/A") -> N/A | W23: =IF(OR(V23="N/A",$B23="N/A"),"N/A",V23*$B23) -> N/A | X23: =IF(OR(W23="N/A",W22="N/A"),"N/A",W23/W22-1) -> N/A | Y23: =_xlfn.XLOOKUP($A23,Chevron!A:A,Chevron!B:B,"N/A") -> N/A | Z23: =IF(OR(Y23="N/A",$B23="N/A"),"N/A",Y23*$B23) -> N/A | AA23: =IF(OR(Z23="N/A",Z22="N/A"),"N/A",Z23/Z22-1) -> N/A | AB23: =_xlfn.XLOOKUP($A23,Boeing!A:A,Boeing!B:B,"N/A") -> N/A | AC23: =IF(OR(AB23="N/A",$B23="N/A"),"N/A",AB23*$B23) -> N/A | AD23: =IF(OR(AC23="N/A",AC22="N/A"),"N/A",AC23/AC22-1) -> N/A | AE23: =_xlfn.XLOOKUP(A23,Amazon!A:A,Amazon!B:B,"N/A") -> N/A | AF23: =IF(OR(AE23="N/A",$B23="N/A"),"N/A",AE23*$B23) -> N/A | AG23: =IF(OR(AF23="N/A",AF22="N/A"),"N/A",AF23/AF22-1) -> N/A | AH23: N/A | AI23: N/A | AJ23: N/A
A24: 45222 | B24: =_xlfn.XLOOKUP(A24,'USD RUB'!B:B,'USD RUB'!C:C,"N/A") -> N/A | C24: =IFERROR(EXP(_xlfn.XLOOKUP(A24,'Bonds (CP)'!$A$4:$A$513,'Work Sheet'!$B$3:$B$512)/252)-1,"N/A") -> 0.47116932 | D24: =IFERROR(_xlfn.XLOOKUP($A24,Intel!$A$2:$A$502,Intel!$B$2:$B$502),"N/A") -> 33.85 | E24: =IF(OR(D24="N/A", $B24="N/A"),"N/A",D24*$B24) -> N/A | F24: =IF(E23="N/A", "N/A", IF(OR(E24="N/A",E23="N/A"),"N/A",E24/E23-1)) -> N/A | G24: =IFERROR(_xlfn.XLOOKUP(A24,Apple!A:A,Apple!B:B),"N/A") -> 173 | H24: =IF(OR(G24="N/A", B24="N/A"),"N/A",G24*$B24) -> N/A | I24: =IF(OR(H24="N/A",H23="N/A"), "N/A", H24/H23-1) -> N/A | J24: =IFERROR(_xlfn.XLOOKUP(A24,Microsoft!A:A,Microsoft!B:B),"N/A") -> 329.32 | K24: =IF(OR(J24="N/A",B24="N/A"),"N/A",J24*B24) -> N/A | L24: =IF(OR(K24="N/A",K23="N/A"), "N/A", K24/K23-1) -> N/A | M24: =IFERROR(_xlfn.XLOOKUP($A24,Cisco!A:A,Cisco!B:B),"N/A") -> 52.2 | N24: =IF(OR(M24="N/A",$B24="N/A"),"N/A",M24*$B24) -> N/A | O24: =IF(OR(N24="N/A",N23="N/A"),"N/A",N24/N23-1) -> N/A | P24: =IFERROR(_xlfn.XLOOKUP($A24,Disney!A:A,Disney!B:B),"N/A") -> 83.1 | Q24: =IF(OR(P24="N/A",$B24="N/A"),"N/A",P24*$B24) -> N/A | R24: =IF(OR(Q24="N/A",Q23="N/A"),"N/A",Q24/Q23-1) -> N/A | S24: =_xlfn.XLOOKUP(A24,FedEx!A:A,FedEx!B:B,"N/A") -> 237.97 | T24: =IF(OR(S24="N/A",$B24="N/A"),"N/A",S24*$B24) -> N/A | U24: =IF(OR(T24="N/A",T23="N/A"),"N/A",T24/T23-1) -> N/A | V24: =_xlfn.XLOOKUP($A24,'General Motors'!A:A,'General Motors'!B:B,"N/A") -> 29.22 | W24: =IF(OR(V24="N/A",$B24="N/A"),"N/A",V24*$B24) -> N/A | X24: =IF(OR(W24="N/A",W23="N/A"),"N/A",W24/W23-1) -> N/A | Y24: =_xlfn.XLOOKUP($A24,Chevron!A:A,Chevron!B:B,"N/A") -> 160.68 | Z24: =IF(OR(Y24="N/A",$B24="N/A"),"N/A",Y24*$B24) -> N/A | AA24: =IF(OR(Z24="N/A",Z23="N/A"),"N/A",Z24/Z23-1) -> N/A | AB24: =_xlfn.XLOOKUP($A24,Boeing!A:A,Boeing!B:B,"N/A") -> 181.03 | AC24: =IF(OR(AB24="N/A",$B24="N/A"),"N/A",AB24*$B24) -> N/A | AD24: =IF(OR(AC24="N/A",AC23="N/A"),"N/A",AC24/AC23-1) -> N/A | AE24: =_xlfn.XLOOKUP(A24,Amazon!A:A,Amazon!B:B,"N/A") -> 126.56 | AF24: =IF(OR(AE24="N/A",$B24="N/A"),"N/A",AE24*$B24) -> N/A | AG24: =IF(OR(AF24="N/A",AF23="N/A"),"N/A",AF24/AF23-1) -> N/A | AH24: 846359 | AI24: N/A | AJ24: N/A
A25: 45223 | B25: =_xlfn.XLOOKUP(A25,'USD RUB'!B:B,'USD RUB'!C:C,"N/A") -> 94.7081 | C25: =IFERROR(EXP(_xlfn.XLOOKUP(A25,'Bonds (CP)'!$A$4:$A$513,'Work Sheet'!$B$3:$B$512)/252)-1,"N/A") -> 0.47151555 | D25: =IFERROR(_xlfn.XLOOKUP($A25,Intel!$A$2:$A$502,Intel!$B$2:$B$502),"N/A") -> 34.59 | E25: =IF(OR(D25="N/A", $B25="N/A"),"N/A",D25*$B25) -> 3275.9532 | F25: =IF(E24="N/A", "N/A", IF(OR(E25="N/A",E24="N/A"),"N/A",E25/E24-1)) -> N/A | G25: =IFERROR(_xlfn.XLOOKUP(A25,Apple!A:A,Apple!B:B),"N/A") -> 173.44 | H25: =IF(OR(G25="N/A", B25="N/A"),"N/A",G25*$B25) -> 16426.173 | I25: =IF(OR(H25="N/A",H24="N/A"), "N/A", H25/H24-1) -> N/A | J25: =IFERROR(_xlfn.XLOOKUP(A25,Microsoft!A:A,Microsoft!B:B),"N/A") -> 330.53 | K25: =IF(OR(J25="N/A",B25="N/A"),"N/A",J25*B25) -> 31303.868 | L25: =IF(OR(K25="N/A",K24="N/A"), "N/A", K25/K24-1) -> N/A | M25: =IFERROR(_xlfn.XLOOKUP($A25,Cisco!A:A,Cisco!B:B),"N/A") -> 53.01 | N25: =IF(OR(M25="N/A",$B25="N/A"),"N/A",M25*$B25) -> 5020.4764 | O25: =IF(OR(N25="N/A",N24="N/A"),"N/A",N25/N24-1) -> N/A | P25: =IFERROR(_xlfn.XLOOKUP($A25,Disney!A:A,Disney!B:B),"N/A") -> 82.56 | Q25: =IF(OR(P25="N/A",$B25="N/A"),"N/A",P25*$B25) -> 7819.1007 | R25: =IF(OR(Q25="N/A",Q24="N/A"),"N/A",Q25/Q24-1) -> N/A | S25: =_xlfn.XLOOKUP(A25,FedEx!A:A,FedEx!B:B,"N/A") -> 241.68 | T25: =IF(OR(S25="N/A",$B25="N/A"),"N/A",S25*$B25) -> 22889.054 | U25: =IF(OR(T25="N/A",T24="N/A"),"N/A",T25/T24-1) -> N/A | V25: =_xlfn.XLOOKUP($A25,'General Motors'!A:A,'General Motors'!B:B,"N/A") -> 28.56 | W25: =IF(OR(V25="N/A",$B25="N/A"),"N/A",V25*$B25) -> 2704.8633 | X25: =IF(OR(W25="N/A",W24="N/A"),"N/A",W25/W24-1) -> N/A | Y25: =_xlfn.XLOOKUP($A25,Chevron!A:A,Chevron!B:B,"N/A") -> 156.65 | Z25: =IF(OR(Y25="N/A",$B25="N/A"),"N/A",Y25*$B25) -> 14836.024 | AA25: =IF(OR(Z25="N/A",Z24="N/A"),"N/A",Z25/Z24-1) -> N/A | AB25: =_xlfn.XLOOKUP($A25,Boeing!A:A,Boeing!B:B,"N/A") -> 182.36 | AC25: =IF(OR(AB25="N/A",$B25="N/A"),"N/A",AB25*$B25) -> 17270.969 | AD25: =IF(OR(AC25="N/A",AC24="N/A"),"N/A",AC25/AC24-1) -> N/A | AE25: =_xlfn.XLOOKUP(A25,Amazon!A:A,Amazon!B:B,"N/A") -> 128.56 | AF25: =IF(OR(AE25="N/A",$B25="N/A"),"N/A",AE25*$B25) -> 12175.673 | AG25: =IF(OR(AF25="N/A",AF24="N/A"),"N/A",AF25/AF24-1) -> N/A | AH25: 4247.68 | AI25: 402289.7 | AJ25: N/A
A26: 45224 | B26: =_xlfn.XLOOKUP(A26,'USD RUB'!B:B,'USD RUB'!C:C,"N/A") -> 93.5224 | C26: =IFERROR(EXP(_xlfn.XLOOKUP(A26,'Bonds (CP)'!$A$4:$A$513,'Work Sheet'!$B$3:$B$512)/252)-1,"N/A") -> 0.47167089 | D26: =IFERROR(_xlfn.XLOOKUP($A26,Intel!$A$2:$A$502,Intel!$B$2:$B$502),"N/A") -> 32.83 | E26: =IF(OR(D26="N/A", $B26="N/A"),"N/A",D26*$B26) -> 3070.3404 | F26: =IF(E25="N/A", "N/A", IF(OR(E26="N/A",E25="N/A"),"N/A",E26/E25-1)) -> -0.062764263 | G26: =IFERROR(_xlfn.XLOOKUP(A26,Apple!A:A,Apple!B:B),"N/A") -> 171.1 | H26: =IF(OR(G26="N/A", B26="N/A"),"N/A",G26*$B26) -> 16001.683 | I26: =IF(OR(H26="N/A",H25="N/A"), "N/A", H26/H25-1) -> -0.025842308 | J26: =IFERROR(_xlfn.XLOOKUP(A26,Microsoft!A:A,Microsoft!B:B),"N/A") -> 340.67 | K26: =IF(OR(J26="N/A",B26="N/A"),"N/A",J26*B26) -> 31860.276 | L26: =IF(OR(K26="N/A",K25="N/A"), "N/A", K26/K25-1) -> 0.017774408 | M26: =IFERROR(_xlfn.XLOOKUP($A26,Cisco!A:A,Cisco!B:B),"N/A") -> 52.4 | N26: =IF(OR(M26="N/A",$B26="N/A"),"N/A",M26*$B26) -> 4900.5738 | O26: =IF(OR(N26="N/A",N25="N/A"),"N/A",N26/N25-1) -> -0.023882718 | P26: =IFERROR(_xlfn.XLOOKUP($A26,Disney!A:A,Disney!B:B),"N/A") -> 80.59 | Q26: =IF(OR(P26="N/A",$B26="N/A"),"N/A",P26*$B26) -> 7536.9702 | R26: =IF(OR(Q26="N/A",Q25="N/A"),"N/A",Q26/Q25-1) -> -0.036082221 | S26: =_xlfn.XLOOKUP(A26,FedEx!A:A,FedEx!B:B,"N/A") -> 235.21 | T26: =IF(OR(S26="N/A",$B26="N/A"),"N/A",S26*$B26) -> 21997.404 | U26: =IF(OR(T26="N/A",T25="N/A"),"N/A",T26/T25-1) -> -0.038955298 | V26: =_xlfn.XLOOKUP($A26,'General Motors'!A:A,'General Motors'!B:B,"N/A") -> 29.01 | W26: =IF(OR(V26="N/A",$B26="N/A"),"N/A",V26*$B26) -> 2713.0848 | X26: =IF(OR(W26="N/A",W25="N/A"),"N/A",W26/W25-1) -> 0.0030395207 | Y26: =_xlfn.XLOOKUP($A26,Chevron!A:A,Chevron!B:B,"N/A") -> 155.87 | Z26: =IF(OR(Y26="N/A",$B26="N/A"),"N/A",Y26*$B26) -> 14577.336 | AA26: =IF(OR(Z26="N/A",Z25="N/A"),"N/A",Z26/Z25-1) -> -0.017436436 | AB26: =_xlfn.XLOOKUP($A26,Boeing!A:A,Boeing!B:B,"N/A") -> 177.73 | AC26: =IF(OR(AB26="N/A",$B26="N/A"),"N/A",AB26*$B26) -> 16621.736 | AD26: =IF(OR(AC26="N/A",AC25="N/A"),"N/A",AC26/AC25-1) -> -0.037590998 | AE26: =_xlfn.XLOOKUP(A26,Amazon!A:A,Amazon!B:B,"N/A") -> 121.39 | AF26: =IF(OR(AE26="N/A",$B26="N/A"),"N/A",AE26*$B26) -> 11352.684 | AG26: =IF(OR(AF26="N/A",AF25="N/A"),"N/A",AF26/AF25-1) -> -0.067592911 | AH26: 4186.77 | AI26: 391556.78 | AJ26: -0.0266796
A27: 45225 | B27: =_xlfn.XLOOKUP(A27,'USD RUB'!B:B,'USD RUB'!C:C,"N/A") -> 93.1507 | C27: =IFERROR(EXP(_xlfn.XLOOKUP(A27,'Bonds (CP)'!$A$4:$A$513,'Work Sheet'!$B$3:$B$512)/252)-1,"N/A") -> 0.47129134 | D27: =IFERROR(_xlfn.XLOOKUP($A27,Intel!$A$2:$A$502,Intel!$B$2:$B$502),"N/A") -> 32.52 | E27: =IF(OR(D27="N/A", $B27="N/A"),"N/A",D27*$B27) -> 3029.2608 | F27: =IF(E26="N/A", "N/A", IF(OR(E27="N/A",E26="N/A"),"N/A",E27/E26-1)) -> -0.013379503 | G27: =IFERROR(_xlfn.XLOOKUP(A27,Apple!A:A,Apple!B:B),"N/A") -> 166.89 | H27: =IF(OR(G27="N/A", B27="N/A"),"N/A",G27*$B27) -> 15545.92 | I27: =IF(OR(H27="N/A",H26="N/A"), "N/A", H27/H26-1) -> -0.028482149 | J27: =IFERROR(_xlfn.XLOOKUP(A27,Microsoft!A:A,Microsoft!B:B),"N/A") -> 327.89 | K27: =IF(OR(J27="N/A",B27="N/A"),"N/A",J27*B27) -> 30543.183 | L27: =IF(OR(K27="N/A",K26="N/A"), "N/A", K27/K26-1) -> -0.04133966 | M27: =IFERROR(_xlfn.XLOOKUP($A27,Cisco!A:A,Cisco!B:B),"N/A") -> 51.37 | N27: =IF(OR(M27="N/A",$B27="N/A"),"N/A",M27*$B27) -> 4785.1515 | O27: =IF(OR(N27="N/A",N26="N/A"),"N/A",N27/N26-1) -> -0.023552814 | P27: =IFERROR(_xlfn.XLOOKUP($A27,Disney!A:A,Disney!B:B),"N/A") -> 79.78 | Q27: =IF(OR(P27="N/A",$B27="N/A"),"N/A",P27*$B27) -> 7431.5628 | R27: =IF(OR(Q27="N/A",Q26="N/A"),"N/A",Q27/Q26-1) -> -0.013985377 | S27: =_xlfn.XLOOKUP(A27,FedEx!A:A,FedEx!B:B,"N/A") -> 227.93 | T27: =IF(OR(S27="N/A",$B27="N/A"),"N/A",S27*$B27) -> 21231.839 | U27: =IF(OR(T27="N/A",T26="N/A"),"N/A",T27/T26-1) -> -0.0348025 | V27: =_xlfn.XLOOKUP($A27,'General Motors'!A:A,'General Motors'!B:B,"N/A") -> 28.55 | W27: =IF(OR(V27="N/A",$B27="N/A"),"N/A",V27*$B27) -> 2659.4525 | X27: =IF(OR(W27="N/A",W26="N/A"),"N/A",W27/W26-1) -> -0.019768029 | Y27: =_xlfn.XLOOKUP($A27,Chevron!A:A,Chevron!B:B,"N/A") -> 154.75 | Z27: =IF(OR(Y27="N/A",$B27="N/A"),"N/A",Y27*$B27) -> 14415.071 | AA27: =IF(OR(Z27="N/A",Z26="N/A"),"N/A",Z27/Z26-1) -> -0.011131366 | AB27: =_xlfn.XLOOKUP($A27,Boeing!A:A,Boeing!B:B,"N/A") -> 179.09 | AC27: =IF(OR(AB27="N/A",$B27="N/A"),"N/A",AB27*$B27) -> 16682.359 | AD27: =IF(OR(AC27="N/A",AC26="N/A"),"N/A",AC27/AC26-1) -> 0.0036471949 | AE27: =_xlfn.XLOOKUP(A27,Amazon!A:A,Amazon!B:B,"N/A") -> 119.57 | AF27: =IF(OR(AE27="N/A",$B27="N/A"),"N/A",AE27*$B27) -> 11138.029 | AG27: =IF(OR(AF27="N/A",AF26="N/A"),"N/A",AF27/AF26-1) -> -0.018907858 | AH27: 4137.23 | AI27: 385385.87 | AJ27: -0.0157599
